Workbook

Sheet Feuil1
A1: Année | B1: 2026 | D1: Jour férie | E1: Valeur retour
D2: =DATE($B$1,1,1) -> 46023 | E2: Oui
D3: =FLOOR(DAY(MINUTE($B$1/38)/2+56)&"/5/"&$B$1,7)-34 -> 46117 | E3: Oui
D4: =D3 + 1 -> 46118 | E4: Oui
D5: =DATE($B$1,5,1) -> 46143 | E5: Oui
D6: =DATE($B$1,5,8) -> 46150 | E6: Oui
D7: =D3+"39" -> 46156 | E7: Oui
D8: =D3 + 49 -> 46166 | E8: Oui
D9: =D3 + 50 -> 46167 | E9: Oui
D10: =DATE($B$1,7,14) -> 46217 | E10: Oui
D11: =DATE($B$1,8,15) -> 46249 | E11: Oui
D12: =DATE($B$1,11,1) -> 46327 | E12: Oui
D13: =DATE($B$1,11,11) -> 46337 | E13: Oui
D14: =DATE($B$1,12,25) -> 46381 | E14: Oui
D15: 46023 | E15: Oui

Sheet AOUT 2026
A1: CALENDRIER CLOTURE AOUT 2026
A2: ARRETE | B2: TRAITEMENT | C2: RESTITUTION | D2: Date de Référence J
A3: Date limite de remontée des PV pour mise en service des investissements | E3: =IF(G3="J",D3,WORKDAY(D$53,MID(G3,2,3),Feuil1!D$2:D$14)) -> 46253 | F3: Matin | G3: J-8
A4: Campagne Fournisseurs Virements Tiers Express | E4: =IF(G4="J",D4,WORKDAY(D$53,MID(G4,2,3),Feuil1!D$2:D$14)) -> 46253 | F4: Nuit | G4: J-8
A5: Premiers relevés de compteurs et de stocks | E5: =IF(G5="J",D5,WORKDAY(D$53,MID(G5,2,3),Feuil1!D$2:D$14)) -> 46254 | F5: Matin | G5: J-7
A6: Campagne Fournisseurs Virements Tiers Express | E6: =IF(G6="J",D6,WORKDAY(D$53,MID(G6,2,3),Feuil1!D$2:D$14)) -> 46254 | F6: Nuit | G6: J-7
B7: Incorporation en comptabilité des écritures GL de paie | E7: =IF(G7="J",D7,WORKDAY(D$53,MID(G7,2,3),Feuil1!D$2:D$14)) -> 46255 | F7: Nuit | G7: J-6
A8: Campagne Fournisseurs Virements Tiers Express | E8: =IF(G8="J",D8,WORKDAY(D$53,MID(G8,2,3),Feuil1!D$2:D$14)) -> 46255 | F8: Nuit | G8: J-6
A9: ARCAS | B9: Envoi à la compta Siège du fichier PROGEFI par le service Trésorerie incluant les remarques des Uos | E9: =IF(G9="J",D9,WORKDAY(D$53,MID(G9,2,3),Feuil1!D$2:D$14)) -> 46258 | F9: Matin | G9: J-5
A10: Fermeture du livre comptable FA | E10: =IF(G10="J",D10,WORKDAY(D$53,MID(G10,2,3),Feuil1!D$2:D$14)) -> 46258 | F10: Soir | G10: J-5
B11: Premier passage des abonnements GL dans Oracle | E11: =IF(G11="J",D11,WORKDAY(D$53,MID(G11,2,3),Feuil1!D$2:D$14)) -> 46258 | F11: Nuit | G11: J-5
B12: Incorporation des écritures d'amortissements | E12: =IF(G12="J",D12,WORKDAY(D$53,MID(G12,2,3),Feuil1!D$2:D$14)) -> 46258 | F12: Nuit | G12: J-5
B13: Incorporation en comptabilité des écritures GL et provisions DACAR | E13: =IF(G13="J",D13,WORKDAY(D$53,MID(G13,2,3),Feuil1!D$2:D$14)) -> 46258 | F13: Nuit | G13: J-5
A14: Campagne Fournisseurs Virements NDF Employé | E14: =IF(G14="J",D14,WORKDAY(D$53,MID(G14,2,3),Feuil1!D$2:D$14)) -> 46258 | F14: Nuit | G14: J-5
A15: Campagne Fournisseurs Virements Tiers Express | E15: =IF(G15="J",D15,WORKDAY(D$53,MID(G15,2,3),Feuil1!D$2:D$14)) -> 46258 | F15: Nuit | G15: J-5
A16: Date limite d'intégration des factures de carburant et péages (DACAR) | E16: =IF(G16="J",D16,WORKDAY(D$53,MID(G16,2,3),Feuil1!D$2:D$14)) -> 46259 | F16: Journée | G16: J-4
A17: CALLISTO | B17: Derniers retours des Uos (mise à jour navettes : subventions, exceptions) et remarques sur traitement M-1 | E17: =IF(G17="J",D17,WORKDAY(D$53,MID(G17,2,3),Feuil1!D$2:D$14)) -> 46259 | F17: Soir | G17: J-4
A18: ARCAS | B18: Traitement ARCAS pour incorporation des écritures d'abonnement | E18: =IF(G18="J",D18,WORKDAY(D$53,MID(G18,2,3),Feuil1!D$2:D$14)) -> 46259 | F18: Soir | G18: J-4
A19: Dernières transmissions des heures de M.O. | E19: =IF(G19="J",D19,WORKDAY(D$53,MID(G19,2,3),Feuil1!D$2:D$14)) -> 46259 | F19: Soir | G19: J-4
A20: Dernières saisies et validation des relevés de compteur et de stocks et des livraisons | E20: =IF(G20="J",D20,WORKDAY(D$53,MID(G20,2,3),Feuil1!D$2:D$14)) -> 46259 | F20: Soir | G20: J-4
A21: Campagne Fournisseurs Virements Tiers Express | E21: =IF(G21="J",D21,WORKDAY(D$53,MID(G21,2,3),Feuil1!D$2:D$14)) -> 46259 | F21: Nuit | G21: J-4
B22: Second passage des abonnements GL dans Oracle | E22: =IF(G22="J",D22,WORKDAY(D$53,MID(G22,2,3),Feuil1!D$2:D$14)) -> 46259 | F22: Nuit | G22: J-4
B23: Calcul de la M.O. au THO (VACHE) | E23: =IF(G23="J",D23,WORKDAY(D$53,MID(G23,2,3),Feuil1!D$2:D$14)) -> 46259 | F23: Nuit | G23: J-4
A24: CALLISTO | B24: Traitement CALLISTO et incorporation des écritures IFRS + envoi fichiers justificatifs aux Uos | E24: =IF(G24="J",D24,WORKDAY(D$53,MID(G24,2,3),Feuil1!D$2:D$14)) -> 46260 | F24: Soir | G24: J-3
A25: ARCAS | B25: Traitement ARCAS et incorporation des écritures IFRS + envoi fichiers justificatifs aux Uos | E25: =IF(G25="J",D25,WORKDAY(D$53,MID(G25,2,3),Feuil1!D$2:D$14)) -> 46260 | F25: Soir | G25: J-3
A26: Arrêté ventes travaux (CITY) | E26: =IF(G26="J",D26,WORKDAY(D$53,MID(G26,2,3),Feuil1!D$2:D$14)) -> 46260 | F26: Soir | G26: J-3
A27: Délai pour la clôture des taches GT,GX et GS | E27: =IF(G27="J",D27,WORKDAY(D$53,MID(G27,2,3),Feuil1!D$2:D$14)) -> 46260 | F27: Soir | G27: J-3
A28: Arrêté ventes exploitation | E28: =IF(G28="J",D28,WORKDAY(D$53,MID(G28,2,3),Feuil1!D$2:D$14)) -> 46260 | F28: Soir | G28: J-3
A29: Arrêté de saisie des factures Open Portal Campus | E29: =IF(G29="J",D29,WORKDAY(D$53,MID(G29,2,3),Feuil1!D$2:D$14)) -> 46260 | F29: Soir | G29: J-3
B30: Calcul des PAR CID | E30: =IF(G30="J",D30,WORKDAY(D$53,MID(G30,2,3),Feuil1!D$2:D$14)) -> 46260 | F30: Soir | G30: J-3
A31: Arrêté de saisie des factures energies | E31: =IF(G31="J",D31,WORKDAY(D$53,MID(G31,2,3),Feuil1!D$2:D$14)) -> 46260 | F31: Soir | G31: J-3
A32: Campagne Fournisseurs Virements Tiers Express | E32: =IF(G32="J",D32,WORKDAY(D$53,MID(G32,2,3),Feuil1!D$2:D$14)) -> 46260 | F32: Nuit | G32: J-3
B33: Refacturation intra-groupe premier traitement | E33: =IF(G33="J",D33,WORKDAY(D$53,MID(G33,2,3),Feuil1!D$2:D$14)) -> 46260 | F33: Nuit | G33: J-3
B34: Dernier passage des abonnements GL dans Oracle | E34: =IF(G34="J",D34,WORKDAY(D$53,MID(G34,2,3),Feuil1!D$2:D$14)) -> 46260 | F34: Nuit | G34: J-3
B35: Incorporation des écritures de M.O. | E35: =IF(G35="J",D35,WORKDAY(D$53,MID(G35,2,3),Feuil1!D$2:D$14)) -> 46260 | F35: Nuit | G35: J-3
B36: Traitement PIRENE (calcul des CAP, valorisation des stocks, ventes) | E36: =IF(G36="J",D36,WORKDAY(D$53,MID(G36,2,3),Feuil1!D$2:D$14)) -> 46260 | F36: Nuit | G36: J-3
B37: Calcul des CAP Gaz, Chaleur et électricité CELERIS | E37: =IF(G37="J",D37,WORKDAY(D$53,MID(G37,2,3),Feuil1!D$2:D$14)) -> 46260 | F37: Nuit | G37: J-3
C38: Mise à disposition des états de REFAC au format PDF sur le drive pour les régions | E38: =IF(G38="J",D38,WORKDAY(D$53,MID(G38,2,3),Feuil1!D$2:D$14)) -> 46261 | F38: Matin | G38: J-2
A39: Modification manuelle des PAR Exploitation mensuels CID et CAP Céleris | E39: =IF(G39="J",D39,WORKDAY(D$53,MID(G39,2,3),Feuil1!D$2:D$14)) -> 46261 | F39: Journée | G39: J-2
B40: Génération des écritures des PAR Exploitation mensuels CID | E40: =IF(G40="J",D40,WORKDAY(D$53,MID(G40,2,3),Feuil1!D$2:D$14)) -> 46261 | F40: 17H | G40: J-2
...

Sheet JUILLET 2026
A1: CALENDRIER CLOTURE JUILLET 2026
A2: ARRETE | B2: TRAITEMENT | C2: RESTITUTION | D2: Date de Référence J
A3: Date limite de remontée des PV pour mise en service des investissements | E3: =IF(G3="J",D3,WORKDAY(D$53,MID(G3,2,3),Feuil1!D$2:D$14)) -> 46224 | F3: Matin | G3: J-8
A4: Campagne Fournisseurs Virements Tiers Express | E4: =IF(G4="J",D4,WORKDAY(D$53,MID(G4,2,3),Feuil1!D$2:D$14)) -> 46224 | F4: Nuit | G4: J-8
A5: Premiers relevés de compteurs et de stocks | E5: =IF(G5="J",D5,WORKDAY(D$53,MID(G5,2,3),Feuil1!D$2:D$14)) -> 46225 | F5: Matin | G5: J-7
A6: Campagne Fournisseurs Virements Tiers Express | E6: =IF(G6="J",D6,WORKDAY(D$53,MID(G6,2,3),Feuil1!D$2:D$14)) -> 46225 | F6: Nuit | G6: J-7
B7: Incorporation en comptabilité des écritures GL de paie | E7: =IF(G7="J",D7,WORKDAY(D$53,MID(G7,2,3),Feuil1!D$2:D$14)) -> 46225 | F7: Nuit | G7: J-7
A8: Campagne Fournisseurs Virements Tiers Express | E8: =IF(G8="J",D8,WORKDAY(D$53,MID(G8,2,3),Feuil1!D$2:D$14)) -> 46226 | F8: Nuit | G8: J-6
A9: ARCAS | B9: Envoi à la compta Siège du fichier PROGEFI par le service Trésorerie incluant les remarques des Uos | E9: =IF(G9="J",D9,WORKDAY(D$53,MID(G9,2,3),Feuil1!D$2:D$14)) -> 46227 | F9: Matin | G9: J-5
A10: Fermeture du livre comptable FA | E10: =IF(G10="J",D10,WORKDAY(D$53,MID(G10,2,3),Feuil1!D$2:D$14)) -> 46227 | F10: Soir | G10: J-5
B11: Premier passage des abonnements GL dans Oracle | E11: =IF(G11="J",D11,WORKDAY(D$53,MID(G11,2,3),Feuil1!D$2:D$14)) -> 46227 | F11: Nuit | G11: J-5
B12: Incorporation des écritures d'amortissements | E12: =IF(G12="J",D12,WORKDAY(D$53,MID(G12,2,3),Feuil1!D$2:D$14)) -> 46227 | F12: Nuit | G12: J-5
B13: Incorporation en comptabilité des écritures GL et provisions DACAR | E13: =IF(G13="J",D13,WORKDAY(D$53,MID(G13,2,3),Feuil1!D$2:D$14)) -> 46227 | F13: Nuit | G13: J-5
A14: Campagne Fournisseurs Virements Tiers Express | E14: =IF(G14="J",D14,WORKDAY(D$53,MID(G14,2,3),Feuil1!D$2:D$14)) -> 46227 | F14: Nuit | G14: J-5
A15: Date limite d'intégration des factures de carburant et péages (DACAR) | E15: =IF(G15="J",D15,WORKDAY(D$53,MID(G15,2,3),Feuil1!D$2:D$14)) -> 46230 | F15: Journée | G15: J-4
A16: CALLISTO | B16: Derniers retours des Uos (mise à jour navettes : subventions, exceptions) et remarques sur traitement M-1 | E16: =IF(G16="J",D16,WORKDAY(D$53,MID(G16,2,3),Feuil1!D$2:D$14)) -> 46230 | F16: Soir | G16: J-4
A17: ARCAS | B17: Traitement ARCAS pour incorporation des écritures d'abonnement | E17: =IF(G17="J",D17,WORKDAY(D$53,MID(G17,2,3),Feuil1!D$2:D$14)) -> 46230 | F17: Soir | G17: J-4
A18: Dernières transmissions des heures de M.O. | E18: =IF(G18="J",D18,WORKDAY(D$53,MID(G18,2,3),Feuil1!D$2:D$14)) -> 46230 | F18: Soir | G18: J-4
A19: Dernières saisies et validation des relevés de compteur et de stocks et des livraisons | E19: =IF(G19="J",D19,WORKDAY(D$53,MID(G19,2,3),Feuil1!D$2:D$14)) -> 46230 | F19: Soir | G19: J-4
A20: Campagne Fournisseurs Virements NDF Employé | E20: =IF(G20="J",D20,WORKDAY(D$53,MID(G20,2,3),Feuil1!D$2:D$14)) -> 46230 | F20: Nuit | G20: J-4
A21: Campagne Fournisseurs Virements Tiers Express | E21: =IF(G21="J",D21,WORKDAY(D$53,MID(G21,2,3),Feuil1!D$2:D$14)) -> 46230 | F21: Nuit | G21: J-4
B22: Second passage des abonnements GL dans Oracle | E22: =IF(G22="J",D22,WORKDAY(D$53,MID(G22,2,3),Feuil1!D$2:D$14)) -> 46230 | F22: Nuit | G22: J-4
B23: Calcul de la M.O. au THO (VACHE) | E23: =IF(G23="J",D23,WORKDAY(D$53,MID(G23,2,3),Feuil1!D$2:D$14)) -> 46230 | F23: Nuit | G23: J-4
A24: CALLISTO | B24: Traitement CALLISTO et incorporation des écritures IFRS + envoi fichiers justificatifs aux Uos | E24: =IF(G24="J",D24,WORKDAY(D$53,MID(G24,2,3),Feuil1!D$2:D$14)) -> 46231 | F24: Soir | G24: J-3
A25: ARCAS | B25: Traitement ARCAS et incorporation des écritures IFRS + envoi fichiers justificatifs aux Uos | E25: =IF(G25="J",D25,WORKDAY(D$53,MID(G25,2,3),Feuil1!D$2:D$14)) -> 46231 | F25: Soir | G25: J-3
A26: Arrêté ventes travaux (CITY) | E26: =IF(G26="J",D26,WORKDAY(D$53,MID(G26,2,3),Feuil1!D$2:D$14)) -> 46231 | F26: Soir | G26: J-3
A27: Délai pour la clôture des taches GT,GX et GS | E27: =IF(G27="J",D27,WORKDAY(D$53,MID(G27,2,3),Feuil1!D$2:D$14)) -> 46231 | F27: Soir | G27: J-3
A28: Arrêté ventes exploitation | E28: =IF(G28="J",D28,WORKDAY(D$53,MID(G28,2,3),Feuil1!D$2:D$14)) -> 46231 | F28: Soir | G28: J-3
A29: Arrêté de saisie des factures Open Portal Campus | E29: =IF(G29="J",D29,WORKDAY(D$53,MID(G29,2,3),Feuil1!D$2:D$14)) -> 46231 | F29: Soir | G29: J-3
B30: Calcul des PAR CID | E30: =IF(G30="J",D30,WORKDAY(D$53,MID(G30,2,3),Feuil1!D$2:D$14)) -> 46231 | F30: Soir | G30: J-3
A31: Arrêté de saisie des factures energies | E31: =IF(G31="J",D31,WORKDAY(D$53,MID(G31,2,3),Feuil1!D$2:D$14)) -> 46231 | F31: Soir | G31: J-3
A32: Campagne Fournisseurs Virements Tiers Express | E32: =IF(G32="J",D32,WORKDAY(D$53,MID(G32,2,3),Feuil1!D$2:D$14)) -> 46231 | F32: Nuit | G32: J-3
B33: Refacturation intra-groupe premier traitement | E33: =IF(G33="J",D33,WORKDAY(D$53,MID(G33,2,3),Feuil1!D$2:D$14)) -> 46231 | F33: Nuit | G33: J-3
B34: Dernier passage des abonnements GL dans Oracle | E34: =IF(G34="J",D34,WORKDAY(D$53,MID(G34,2,3),Feuil1!D$2:D$14)) -> 46231 | F34: Nuit | G34: J-3
B35: Incorporation des écritures de M.O. | E35: =IF(G35="J",D35,WORKDAY(D$53,MID(G35,2,3),Feuil1!D$2:D$14)) -> 46231 | F35: Nuit | G35: J-3
B36: Traitement PIRENE (calcul des CAP, valorisation des stocks, ventes) | E36: =IF(G36="J",D36,WORKDAY(D$53,MID(G36,2,3),Feuil1!D$2:D$14)) -> 46231 | F36: Nuit | G36: J-3
B37: Calcul des CAP Gaz, Chaleur et électricité CELERIS | E37: =IF(G37="J",D37,WORKDAY(D$53,MID(G37,2,3),Feuil1!D$2:D$14)) -> 46231 | F37: Nuit | G37: J-3
C38: Mise à disposition des états de REFAC au format PDF sur le drive pour les régions | E38: =IF(G38="J",D38,WORKDAY(D$53,MID(G38,2,3),Feuil1!D$2:D$14)) -> 46232 | F38: Matin | G38: J-2
A39: Modification manuelle des PAR Exploitation mensuels CID et CAP Céleris | E39: =IF(G39="J",D39,WORKDAY(D$53,MID(G39,2,3),Feuil1!D$2:D$14)) -> 46232 | F39: Journée | G39: J-2
B40: Génération des écritures des PAR Exploitation mensuels CID | E40: =IF(G40="J",D40,WORKDAY(D$53,MID(G40,2,3),Feuil1!D$2:D$14)) -> 46232 | F40: 17H | G40: J-2
...

Sheet Feuil2
B2: CALENDRIER CLOTURE Juillet 2026
B3: Jour | E3: Jalon | F3: Astreinte | G3: Cockpit
B4: Vendredi 24 Aout | C4: Nuit | D4: J-5 | E4: Cloture FA
B5: Vendredi 31 Aout | C5: Nuit | D5: J | E5: Cloture provisoire | F5: Oui (CtrlM)
B6: Lundi 03 Aout | C6: Matin | D6: J+1 | G6: 8H30
B7: 46267 | C7: Nuit | D7: J+2 | E7: Cloture définitive | F7: Oui (CtrlM)
B8: Mercredi 05 Aout | C8: Matin | D8: J+3 | G8: 8H30

Sheet SEPTEMBRE 2026
A1: CALENDRIER CLOTURE SEPTEMBRE 2026
A2: ARRETE | B2: TRAITEMENT | C2: RESTITUTION | D2: Date de Référence J
A3: Date limite de remontée des PV pour mise en service des investissements | E3: =IF(G3="J",D3,WORKDAY(D$56,MID(G3,2,3),Feuil1!D$2:D$14)) -> 46283 | F3: Matin | G3: J-8
A4: Campagne Fournisseurs Virements Tiers Express | E4: =IF(G4="J",D4,WORKDAY(D$56,MID(G4,2,3),Feuil1!D$2:D$14)) -> 46283 | F4: Nuit | G4: J-8
A5: Premiers relevés de compteurs et de stocks | E5: =IF(G5="J",D5,WORKDAY(D$56,MID(G5,2,3),Feuil1!D$2:D$14)) -> 46286 | F5: Matin | G5: J-7
A6: Campagne Fournisseurs Virements NDF Employé | E6: =IF(G6="J",D6,WORKDAY(D$56,MID(G6,2,3),Feuil1!D$2:D$14)) -> 46286 | F6: Nuit | G6: J-7
A7: Campagne Fournisseurs Virements Tiers Express | E7: =IF(G7="J",D7,WORKDAY(D$56,MID(G7,2,3),Feuil1!D$2:D$14)) -> 46286 | F7: Nuit | G7: J-7
A8: Campagne Fournisseurs Virements Tiers Express | E8: =IF(G8="J",D8,WORKDAY(D$56,MID(G8,2,3),Feuil1!D$2:D$14)) -> 46287 | F8: Nuit | G8: J-6
B9: Incorporation en comptabilité des écritures GL de paie | E9: =IF(G9="J",D9,WORKDAY(D$56,MID(G9,2,3),Feuil1!D$2:D$14)) -> 46288 | F9: Nuit | G9: J-5
C10: Campagne Fournisseurs TIERS FDM - Mise à disposition des échéanciers provisoires | E10: =IF(G10="J",D10,WORKDAY(D$56,MID(G10,2,3),Feuil1!D$2:D$14)) -> 46288 | F10: Matin | G10: J-5
A11: ARCAS | B11: Envoi à la compta Siège du fichier PROGEFI par le service Trésorerie incluant les remarques des Uos | E11: =IF(G11="J",D11,WORKDAY(D$56,MID(G11,2,3),Feuil1!D$2:D$14)) -> 46288 | F11: Matin | G11: J-5
A12: Fermeture du livre comptable FA | E12: =IF(G12="J",D12,WORKDAY(D$56,MID(G12,2,3),Feuil1!D$2:D$14)) -> 46288 | F12: Soir | G12: J-5
B13: Premier passage des abonnements GL dans Oracle | E13: =IF(G13="J",D13,WORKDAY(D$56,MID(G13,2,3),Feuil1!D$2:D$14)) -> 46288 | F13: Nuit | G13: J-5
B14: Incorporation des écritures d'amortissements | E14: =IF(G14="J",D14,WORKDAY(D$56,MID(G14,2,3),Feuil1!D$2:D$14)) -> 46288 | F14: Nuit | G14: J-5
B15: Incorporation en comptabilité des écritures GL et provisions DACAR | E15: =IF(G15="J",D15,WORKDAY(D$56,MID(G15,2,3),Feuil1!D$2:D$14)) -> 46288 | F15: Nuit | G15: J-5
A16: Campagne Fournisseurs TIERS FDM - Mise à disposition des pupitres et envoi du mail de Projection | E16: =IF(G16="J",D16,WORKDAY(D$56,MID(G16,2,3),Feuil1!D$2:D$14)) -> 46289 | F16: Matin | G16: J-4
A17: Date limite d'intégration des factures de carburant et péages (DACAR) | E17: =IF(G17="J",D17,WORKDAY(D$56,MID(G17,2,3),Feuil1!D$2:D$14)) -> 46289 | F17: Journée | G17: J-4
A18: CALLISTO | B18: Derniers retours des Uos (mise à jour navettes : subventions, exceptions) et remarques sur traitement M-1 | E18: =IF(G18="J",D18,WORKDAY(D$56,MID(G18,2,3),Feuil1!D$2:D$14)) -> 46289 | F18: Soir | G18: J-4
A19: ARCAS | B19: Traitement ARCAS pour incorporation des écritures d'abonnement | E19: =IF(G19="J",D19,WORKDAY(D$56,MID(G19,2,3),Feuil1!D$2:D$14)) -> 46289 | F19: Soir | G19: J-4
A20: Dernières transmissions des heures de M.O. | E20: =IF(G20="J",D20,WORKDAY(D$56,MID(G20,2,3),Feuil1!D$2:D$14)) -> 46289 | F20: Soir | G20: J-4
A21: Dernières saisies et validation des relevés de compteur et de stocks et des livraisons | E21: =IF(G21="J",D21,WORKDAY(D$56,MID(G21,2,3),Feuil1!D$2:D$14)) -> 46289 | F21: Soir | G21: J-4
A22: Validation de l'échéancier TIERS FDM + Envoi des ordres de virements à CDPG + Envoi des avis de virements par mail aux Frs | E22: =IF(G22="J",D22,WORKDAY(D$56,MID(G22,2,3),Feuil1!D$2:D$14)) -> 46289 | F22: Soir | G22: J-4
B23: Second passage des abonnements GL dans Oracle | E23: =IF(G23="J",D23,WORKDAY(D$56,MID(G23,2,3),Feuil1!D$2:D$14)) -> 46289 | F23: Nuit | G23: J-4
B24: Calcul de la M.O. au THO (VACHE) | E24: =IF(G24="J",D24,WORKDAY(D$56,MID(G24,2,3),Feuil1!D$2:D$14)) -> 46289 | F24: Nuit | G24: J-4
C25: Envoi du mail de confirmation des virements TIERS FDM | E25: =IF(G25="J",D25,WORKDAY(D$56,MID(G25,2,3),Feuil1!D$2:D$14)) -> 46290 | F25: Matin | G25: J-3
A26: CALLISTO | B26: Traitement CALLISTO et incorporation des écritures IFRS + envoi fichiers justificatifs aux Uos | E26: =IF(G26="J",D26,WORKDAY(D$56,MID(G26,2,3),Feuil1!D$2:D$14)) -> 46290 | F26: Soir | G26: J-3
A27: ARCAS | B27: Traitement ARCAS et incorporation des écritures IFRS + envoi fichiers justificatifs aux Uos | E27: =IF(G27="J",D27,WORKDAY(D$56,MID(G27,2,3),Feuil1!D$2:D$14)) -> 46290 | F27: Soir | G27: J-3
A28: Arrêté ventes travaux (CITY) | E28: =IF(G28="J",D28,WORKDAY(D$56,MID(G28,2,3),Feuil1!D$2:D$14)) -> 46290 | F28: Soir | G28: J-3
A29: Délai pour la clôture des taches GT,GX et GS | E29: =IF(G29="J",D29,WORKDAY(D$56,MID(G29,2,3),Feuil1!D$2:D$14)) -> 46290 | F29: Soir | G29: J-3
A30: Arrêté ventes exploitation | E30: =IF(G30="J",D30,WORKDAY(D$56,MID(G30,2,3),Feuil1!D$2:D$14)) -> 46290 | F30: Soir | G30: J-3
A31: Arrêté de saisie des factures Open Portal Campus | E31: =IF(G31="J",D31,WORKDAY(D$56,MID(G31,2,3),Feuil1!D$2:D$14)) -> 46290 | F31: Soir | G31: J-3
B32: Calcul des PAR CID | E32: =IF(G32="J",D32,WORKDAY(D$56,MID(G32,2,3),Feuil1!D$2:D$14)) -> 46290 | F32: Soir | G32: J-3
A33: Arrêté de saisie des factures energies | E33: =IF(G33="J",D33,WORKDAY(D$56,MID(G33,2,3),Feuil1!D$2:D$14)) -> 46290 | F33: Soir | G33: J-3
A34: Campagne Fournisseurs Virements Tiers Express | E34: =IF(G34="J",D34,WORKDAY(D$56,MID(G34,2,3),Feuil1!D$2:D$14)) -> 46290 | F34: Nuit | G34: J-3
B35: Refacturation intra-groupe premier traitement | E35: =IF(G35="J",D35,WORKDAY(D$56,MID(G35,2,3),Feuil1!D$2:D$14)) -> 46290 | F35: Nuit | G35: J-3
B36: Dernier passage des abonnements GL dans Oracle | E36: =IF(G36="J",D36,WORKDAY(D$56,MID(G36,2,3),Feuil1!D$2:D$14)) -> 46290 | F36: Nuit | G36: J-3
B37: Incorporation des écritures de M.O. | E37: =IF(G37="J",D37,WORKDAY(D$56,MID(G37,2,3),Feuil1!D$2:D$14)) -> 46290 | F37: Nuit | G37: J-3
B38: Traitement PIRENE (calcul des CAP, valorisation des stocks, ventes) | E38: =IF(G38="J",D38,WORKDAY(D$56,MID(G38,2,3),Feuil1!D$2:D$14)) -> 46290 | F38: Nuit | G38: J-3
B39: Calcul des CAP Gaz, Chaleur et électricité CELERIS | E39: =IF(G39="J",D39,WORKDAY(D$56,MID(G39,2,3),Feuil1!D$2:D$14)) -> 46290 | F39: Nuit | G39: J-3
C40: Mise à disposition des états de REFAC au format PDF sur le drive pour les régions | E40: =IF(G40="J",D40,WORKDAY(D$56,MID(G40,2,3),Feuil1!D$2:D$14)) -> 46293 | F40: Matin | G40: J-2
...
