Workbook

Sheet A créer
A1: Société | B1: Région | C1: Nom - Raiso sociale | D1: OU only | E1: Multi | F1: Adresse Fact = Sté | G1: Code conso | H1: Région principale | I1: Sigle - Livre comptable | J1: Numéro & rue | K1: Code postal | L1: ville | M1: Num pour TSA | N1: Numéro & rue | O1: Complément | P1: Compte Banque | Q1: Nom Banque | R1: Projet FPS
A2: 0513 | B2: DRW | C2: DK 27 | D2: Oui | E2: Non | F2: Non | G2: S2327 | H2: DRW | I2: DK 27 | J2: 33, Place des Corolles TOUR EUROPE | K2: 92400 | L2: COURBEVOIE | M2: 18513 | N2: TSA 85501 | O2: 59784 LILLE CEDEX 9 | P2: 513570 | Q2: BNP PARIBAS | R2: FB0084715S
A3: 0412 | B3: DNA | C3: SOCIETE VALMY DEFENSE 108 | D3: Oui | E3: Non | F3: Non | G3: S2008 | H3: DNA | I3: SOCIETE VALMY DEFENSE 108 | J3: 37,AVENUE DU MARECHAL DE LATTRE DE TASSIGNY | K3: 59350 | L3: SAINT-ANDRE LEZ LILLE | M3: XXXXX | N3: TSA 55507 | O3: 59784 LILLE CEDEX 9 | P3: 513479 | Q3: SOCIETE GENERALE | R3: FB0084874Y
A4: 0505 | B4: DMS | C4: MONTCHOVET ENERGIES | D4: Oui | E4: Non | F4: Non | G4: YS2121 | H4: DMS | I4: MONTCHOVET ENERGIES | J4: 15, AV ALBERT EINSTEIN TOUR EUROPE - TSA 77655 | K4: 69100 | L4: VILLEURBANNE | M4: 53505 | N4: TSA 35505 | O4: 59784 LILLE CEDEX 9 | P4: 513564 | Q4: BNP PARIBAS | R4: FB0084664J
A6: 0401 | B6: DRW | C6: SOCIETE VALMY DEFENSE 101 | D6: Non | E6: Non | F6: Non | G6: S0101 | H6: DRW | I6: SVD 101 | J6: TOUR EUROPE - 33 , PLACE DES COROLLES | K6: 92400 | L6: COURBEVOIE | M6: 18401 | N6: TSA 85501 | O6: 59784 LILLE CEDEX 9 | P6: 513472 | Q6: SOCIETE GENERALE | R6: FB0090202C
A7: 0554 | B7: DNA | C7: DK 52 | D7: Oui | E7: Non | F7: Non | G7: YS2352 | H7: DNA | I7: DK 52 | J7: 4B, RUE FRANCOISE D'EAUBONNE | K7: 31200 | L7: TOULOUSE | M7: 57554 | N7: TSA 55507 | O7: 59784 LILLE CEDEX 9 | P7: 513603 | Q7: BNP PARIBAS | R7: FB0090378C

Sheet Regroupement
A1: *FN | B1: Code | C1: Tab | D1: Nom | E1: Tab | F1: Description | G1: *SAVE
A2: =IF(OR('A créer'!D2="Oui",LEN('A créer'!D2)=0),"","*FN") | B2: =IF(OR('A créer'!D2="Oui",LEN('A créer'!D2)=0),"",CONCATENATE("A",'A créer'!A2)) | C2: =IF(OR('A créer'!D2="Oui",LEN('A créer'!D2)=0),"","Tab") | D2: =IF(OR('A créer'!D2="Oui",LEN('A créer'!D2)=0),"",CONCATENATE("A",'A créer'!A2)) | E2: =IF(OR('A créer'!D2="Oui",LEN('A créer'!D2)=0),"","Tab") | F2: =IF(OR('A créer'!D2="Oui",LEN('A créer'!D2)=0),"",CONCATENATE("STE ",'A créer'!A2)) | G2: =IF(OR('A créer'!D2="Oui",LEN('A créer'!D2)=0),"","*SAVE")
A3: =IF(OR('A créer'!D3="Oui",LEN('A créer'!D3)=0),"","*FN") | B3: =IF(OR('A créer'!D3="Oui",LEN('A créer'!D3)=0),"",CONCATENATE("A",'A créer'!A3)) | C3: =IF(OR('A créer'!D3="Oui",LEN('A créer'!D3)=0),"","Tab") | D3: =IF(OR('A créer'!D3="Oui",LEN('A créer'!D3)=0),"",CONCATENATE("A",'A créer'!A3)) | E3: =IF(OR('A créer'!D3="Oui",LEN('A créer'!D3)=0),"","Tab") | F3: =IF(OR('A créer'!D3="Oui",LEN('A créer'!D3)=0),"",CONCATENATE("STE ",'A créer'!A3)) | G3: =IF(OR('A créer'!D3="Oui",LEN('A créer'!D3)=0),"","*SAVE")
A4: =IF(OR('A créer'!D4="Oui",LEN('A créer'!D4)=0),"","*FN") | B4: =IF(OR('A créer'!D4="Oui",LEN('A créer'!D4)=0),"",CONCATENATE("A",'A créer'!A4)) | C4: =IF(OR('A créer'!D4="Oui",LEN('A créer'!D4)=0),"","Tab") | D4: =IF(OR('A créer'!D4="Oui",LEN('A créer'!D4)=0),"",CONCATENATE("A",'A créer'!A4)) | E4: =IF(OR('A créer'!D4="Oui",LEN('A créer'!D4)=0),"","Tab") | F4: =IF(OR('A créer'!D4="Oui",LEN('A créer'!D4)=0),"",CONCATENATE("STE ",'A créer'!A4)) | G4: =IF(OR('A créer'!D4="Oui",LEN('A créer'!D4)=0),"","*SAVE")
A5: =IF(OR('A créer'!D5="Oui",LEN('A créer'!D5)=0),"","*FN") | B5: =IF(OR('A créer'!D5="Oui",LEN('A créer'!D5)=0),"",CONCATENATE("A",'A créer'!A5)) | C5: =IF(OR('A créer'!D5="Oui",LEN('A créer'!D5)=0),"","Tab") | D5: =IF(OR('A créer'!D5="Oui",LEN('A créer'!D5)=0),"",CONCATENATE("A",'A créer'!A5)) | E5: =IF(OR('A créer'!D5="Oui",LEN('A créer'!D5)=0),"","Tab") | F5: =IF(OR('A créer'!D5="Oui",LEN('A créer'!D5)=0),"",CONCATENATE("STE ",'A créer'!A5)) | G5: =IF(OR('A créer'!D5="Oui",LEN('A créer'!D5)=0),"","*SAVE")
A6: =IF(OR('A créer'!D6="Oui",LEN('A créer'!D6)=0),"","*FN") -> *FN | B6: =IF(OR('A créer'!D6="Oui",LEN('A créer'!D6)=0),"",CONCATENATE("A",'A créer'!A6)) -> A0401 | C6: =IF(OR('A créer'!D6="Oui",LEN('A créer'!D6)=0),"","Tab") -> Tab | D6: =IF(OR('A créer'!D6="Oui",LEN('A créer'!D6)=0),"",CONCATENATE("A",'A créer'!A6)) -> A0401 | E6: =IF(OR('A créer'!D6="Oui",LEN('A créer'!D6)=0),"","Tab") -> Tab | F6: =IF(OR('A créer'!D6="Oui",LEN('A créer'!D6)=0),"",CONCATENATE("STE ",'A créer'!A6)) -> STE 0401 | G6: =IF(OR('A créer'!D6="Oui",LEN('A créer'!D6)=0),"","*SAVE") -> *SAVE
A7: =IF(OR('A créer'!D7="Oui",LEN('A créer'!D7)=0),"","*FN") | B7: =IF(OR('A créer'!D7="Oui",LEN('A créer'!D7)=0),"",CONCATENATE("A",'A créer'!A7)) | C7: =IF(OR('A créer'!D7="Oui",LEN('A créer'!D7)=0),"","Tab") | D7: =IF(OR('A créer'!D7="Oui",LEN('A créer'!D7)=0),"",CONCATENATE("A",'A créer'!A7)) | E7: =IF(OR('A créer'!D7="Oui",LEN('A créer'!D7)=0),"","Tab") | F7: =IF(OR('A créer'!D7="Oui",LEN('A créer'!D7)=0),"",CONCATENATE("STE ",'A créer'!A7)) | G7: =IF(OR('A créer'!D7="Oui",LEN('A créer'!D7)=0),"","*SAVE")
A8: =IF(OR('A créer'!D8="Oui",LEN('A créer'!D8)=0),"","*FN") | B8: =IF(OR('A créer'!D8="Oui",LEN('A créer'!D8)=0),"",CONCATENATE("A",'A créer'!A8)) | C8: =IF(OR('A créer'!D8="Oui",LEN('A créer'!D8)=0),"","Tab") | D8: =IF(OR('A créer'!D8="Oui",LEN('A créer'!D8)=0),"",CONCATENATE("A",'A créer'!A8)) | E8: =IF(OR('A créer'!D8="Oui",LEN('A créer'!D8)=0),"","Tab") | F8: =IF(OR('A créer'!D8="Oui",LEN('A créer'!D8)=0),"",CONCATENATE("STE ",'A créer'!A8)) | G8: =IF(OR('A créer'!D8="Oui",LEN('A créer'!D8)=0),"","*SAVE")
A9: =IF(OR('A créer'!D9="Oui",LEN('A créer'!D9)=0),"","*FN") | B9: =IF(OR('A créer'!D9="Oui",LEN('A créer'!D9)=0),"",CONCATENATE("A",'A créer'!A9)) | C9: =IF(OR('A créer'!D9="Oui",LEN('A créer'!D9)=0),"","Tab") | D9: =IF(OR('A créer'!D9="Oui",LEN('A créer'!D9)=0),"",CONCATENATE("A",'A créer'!A9)) | E9: =IF(OR('A créer'!D9="Oui",LEN('A créer'!D9)=0),"","Tab") | F9: =IF(OR('A créer'!D9="Oui",LEN('A créer'!D9)=0),"",CONCATENATE("STE ",'A créer'!A9)) | G9: =IF(OR('A créer'!D9="Oui",LEN('A créer'!D9)=0),"","*SAVE")
A10: =IF(OR('A créer'!D10="Oui",LEN('A créer'!D10)=0),"","*FN") | B10: =IF(OR('A créer'!D10="Oui",LEN('A créer'!D10)=0),"",CONCATENATE("A",'A créer'!A10)) | C10: =IF(OR('A créer'!D10="Oui",LEN('A créer'!D10)=0),"","Tab") | D10: =IF(OR('A créer'!D10="Oui",LEN('A créer'!D10)=0),"",CONCATENATE("A",'A créer'!A10)) | E10: =IF(OR('A créer'!D10="Oui",LEN('A créer'!D10)=0),"","Tab") | F10: =IF(OR('A créer'!D10="Oui",LEN('A créer'!D10)=0),"",CONCATENATE("STE ",'A créer'!A10)) | G10: =IF(OR('A créer'!D10="Oui",LEN('A créer'!D10)=0),"","*SAVE")
A11: =IF(OR('A créer'!D11="Oui",LEN('A créer'!D11)=0),"","*FN") | B11: =IF(OR('A créer'!D11="Oui",LEN('A créer'!D11)=0),"",CONCATENATE("A",'A créer'!A11)) | C11: =IF(OR('A créer'!D11="Oui",LEN('A créer'!D11)=0),"","Tab") | D11: =IF(OR('A créer'!D11="Oui",LEN('A créer'!D11)=0),"",CONCATENATE("A",'A créer'!A11)) | E11: =IF(OR('A créer'!D11="Oui",LEN('A créer'!D11)=0),"","Tab") | F11: =IF(OR('A créer'!D11="Oui",LEN('A créer'!D11)=0),"",CONCATENATE("STE ",'A créer'!A11)) | G11: =IF(OR('A créer'!D11="Oui",LEN('A créer'!D11)=0),"","*SAVE")
A12: =IF(OR('A créer'!D12="Oui",LEN('A créer'!D12)=0),"","*FN") | B12: =IF(OR('A créer'!D12="Oui",LEN('A créer'!D12)=0),"",CONCATENATE("A",'A créer'!A12)) | C12: =IF(OR('A créer'!D12="Oui",LEN('A créer'!D12)=0),"","Tab") | D12: =IF(OR('A créer'!D12="Oui",LEN('A créer'!D12)=0),"",CONCATENATE("A",'A créer'!A12)) | E12: =IF(OR('A créer'!D12="Oui",LEN('A créer'!D12)=0),"","Tab") | F12: =IF(OR('A créer'!D12="Oui",LEN('A créer'!D12)=0),"",CONCATENATE("STE ",'A créer'!A12)) | G12: =IF(OR('A créer'!D12="Oui",LEN('A créer'!D12)=0),"","*SAVE")
A13: =IF(OR('A créer'!D13="Oui",LEN('A créer'!D13)=0),"","*FN") | B13: =IF(OR('A créer'!D13="Oui",LEN('A créer'!D13)=0),"",CONCATENATE("A",'A créer'!A13)) | C13: =IF(OR('A créer'!D13="Oui",LEN('A créer'!D13)=0),"","Tab") | D13: =IF(OR('A créer'!D13="Oui",LEN('A créer'!D13)=0),"",CONCATENATE("A",'A créer'!A13)) | E13: =IF(OR('A créer'!D13="Oui",LEN('A créer'!D13)=0),"","Tab") | F13: =IF(OR('A créer'!D13="Oui",LEN('A créer'!D13)=0),"",CONCATENATE("STE ",'A créer'!A13)) | G13: =IF(OR('A créer'!D13="Oui",LEN('A créer'!D13)=0),"","*SAVE")
... A30: =IF(OR('A créer'!D30="Oui",LEN('A créer'!D30)=0),"","*FN") | B30: =IF(OR('A créer'!D30="Oui",LEN('A créer'!D30)=0),"",CONCATENATE("A",'A créer'!A30)) | C30: =IF(OR('A créer'!D30="Oui",LEN('A créer'!D30)=0),"","Tab") | D30: =IF(OR('A créer'!D30="Oui",LEN('A créer'!D30)=0),"",CONCATENATE("A",'A créer'!A30)) | E30: =IF(OR('A créer'!D30="Oui",LEN('A créer'!D30)=0),"","Tab") | F30: =IF(OR('A créer'!D30="Oui",LEN('A créer'!D30)=0),"",CONCATENATE("STE ",'A créer'!A30)) | G30: =IF(OR('A créer'!D30="Oui",LEN('A créer'!D30)=0),"","*SAVE")

Sheet XDKA_ARGOS_INTERCO
A1: *FN | B1: Code | C1: Tab | D1: Description | E1: Tab | F1: *SAVE
A2: =IF(LEN('A créer'!G2)=0,"","*FN") -> *FN | B2: =IF(LEN('A créer'!G2)=0,"",'A créer'!G2) -> S2327 | C2: =IF(LEN('A créer'!G2)=0,"","Tab") -> Tab | D2: =IF(LEN('A créer'!G2)=0,IF(LEN('A créer'!G2)>0,CONCATENATE('A créer'!C2," ",'A créer'!B2),""),'A créer'!C2) -> DK 27 | E2: =IF(LEN('A créer'!G2)=0,"","Tab") -> Tab | F2: =IF(LEN('A créer'!G2)=0,"","*SAVE") -> *SAVE
A3: =IF(LEN('A créer'!G3)=0,"","*FN") -> *FN | B3: =IF(LEN('A créer'!G3)=0,"",'A créer'!G3) -> S2008 | C3: =IF(LEN('A créer'!G3)=0,"","Tab") -> Tab | D3: =IF(LEN('A créer'!G3)=0,IF(LEN('A créer'!G3)>0,CONCATENATE('A créer'!C3," ",'A créer'!B3),""),'A créer'!C3) -> SOCIETE VALMY DEFENSE 108 | E3: =IF(LEN('A créer'!G3)=0,"","Tab") -> Tab | F3: =IF(LEN('A créer'!G3)=0,"","*SAVE") -> *SAVE
A4: =IF(LEN('A créer'!G4)=0,"","*FN") -> *FN | B4: =IF(LEN('A créer'!G4)=0,"",'A créer'!G4) -> YS2121 | C4: =IF(LEN('A créer'!G4)=0,"","Tab") -> Tab | D4: =IF(LEN('A créer'!G4)=0,IF(LEN('A créer'!G4)>0,CONCATENATE('A créer'!C4," ",'A créer'!B4),""),'A créer'!C4) -> MONTCHOVET ENERGIES | E4: =IF(LEN('A créer'!G4)=0,"","Tab") -> Tab | F4: =IF(LEN('A créer'!G4)=0,"","*SAVE") -> *SAVE
A5: =IF(LEN('A créer'!G5)=0,"","*FN") | B5: =IF(LEN('A créer'!G5)=0,"",'A créer'!G5) | C5: =IF(LEN('A créer'!G5)=0,"","Tab") | D5: =IF(LEN('A créer'!G5)=0,IF(LEN('A créer'!G5)>0,CONCATENATE('A créer'!C5," ",'A créer'!B5),""),'A créer'!C5) | E5: =IF(LEN('A créer'!G5)=0,"","Tab") | F5: =IF(LEN('A créer'!G5)=0,"","*SAVE")
A6: =IF(LEN('A créer'!G6)=0,"","*FN") -> *FN | B6: =IF(LEN('A créer'!G6)=0,"",'A créer'!G6) -> S0101 | C6: =IF(LEN('A créer'!G6)=0,"","Tab") -> Tab | D6: =IF(LEN('A créer'!G6)=0,IF(LEN('A créer'!G6)>0,CONCATENATE('A créer'!C6," ",'A créer'!B6),""),'A créer'!C6) -> SOCIETE VALMY DEFENSE 101 | E6: =IF(LEN('A créer'!G6)=0,"","Tab") -> Tab | F6: =IF(LEN('A créer'!G6)=0,"","*SAVE") -> *SAVE
A7: =IF(LEN('A créer'!G7)=0,"","*FN") -> *FN | B7: =IF(LEN('A créer'!G7)=0,"",'A créer'!G7) -> YS2352 | C7: =IF(LEN('A créer'!G7)=0,"","Tab") -> Tab | D7: =IF(LEN('A créer'!G7)=0,IF(LEN('A créer'!G7)>0,CONCATENATE('A créer'!C7," ",'A créer'!B7),""),'A créer'!C7) -> DK 52 | E7: =IF(LEN('A créer'!G7)=0,"","Tab") -> Tab | F7: =IF(LEN('A créer'!G7)=0,"","*SAVE") -> *SAVE
A8: =IF(LEN('A créer'!G8)=0,"","*FN") | B8: =IF(LEN('A créer'!G8)=0,"",'A créer'!G8) | C8: =IF(LEN('A créer'!G8)=0,"","Tab") | D8: =IF(LEN('A créer'!G8)=0,IF(LEN('A créer'!G8)>0,CONCATENATE('A créer'!C8," ",'A créer'!B8),""),'A créer'!C8) | E8: =IF(LEN('A créer'!G8)=0,"","Tab") | F8: =IF(LEN('A créer'!G8)=0,"","*SAVE")
A9: =IF(LEN('A créer'!G9)=0,"","*FN") | B9: =IF(LEN('A créer'!G9)=0,"",'A créer'!G9) | C9: =IF(LEN('A créer'!G9)=0,"","Tab") | D9: =IF(LEN('A créer'!G9)=0,IF(LEN('A créer'!G9)>0,CONCATENATE('A créer'!C9," ",'A créer'!B9),""),'A créer'!C9) | E9: =IF(LEN('A créer'!G9)=0,"","Tab") | F9: =IF(LEN('A créer'!G9)=0,"","*SAVE")
A10: =IF(LEN('A créer'!G10)=0,"","*FN") | B10: =IF(LEN('A créer'!G10)=0,"",'A créer'!G10) | C10: =IF(LEN('A créer'!G10)=0,"","Tab") | D10: =IF(LEN('A créer'!G10)=0,IF(LEN('A créer'!G10)>0,CONCATENATE('A créer'!C10," ",'A créer'!B10),""),'A créer'!C10) | E10: =IF(LEN('A créer'!G10)=0,"","Tab") | F10: =IF(LEN('A créer'!G10)=0,"","*SAVE")
A11: =IF(LEN('A créer'!G11)=0,"","*FN") | B11: =IF(LEN('A créer'!G11)=0,"",'A créer'!G11) | C11: =IF(LEN('A créer'!G11)=0,"","Tab") | D11: =IF(LEN('A créer'!G11)=0,IF(LEN('A créer'!G11)>0,CONCATENATE('A créer'!C11," ",'A créer'!B11),""),'A créer'!C11) | E11: =IF(LEN('A créer'!G11)=0,"","Tab") | F11: =IF(LEN('A créer'!G11)=0,"","*SAVE")
A12: =IF(LEN('A créer'!G12)=0,"","*FN") | B12: =IF(LEN('A créer'!G12)=0,"",'A créer'!G12) | C12: =IF(LEN('A créer'!G12)=0,"","Tab") | D12: =IF(LEN('A créer'!G12)=0,IF(LEN('A créer'!G12)>0,CONCATENATE('A créer'!C12," ",'A créer'!B12),""),'A créer'!C12) | E12: =IF(LEN('A créer'!G12)=0,"","Tab") | F12: =IF(LEN('A créer'!G12)=0,"","*SAVE")
A13: =IF(LEN('A créer'!G13)=0,"","*FN") | B13: =IF(LEN('A créer'!G13)=0,"",'A créer'!G13) | C13: =IF(LEN('A créer'!G13)=0,"","Tab") | D13: =IF(LEN('A créer'!G13)=0,IF(LEN('A créer'!G13)>0,CONCATENATE('A créer'!C13," ",'A créer'!B13),""),'A créer'!C13) | E13: =IF(LEN('A créer'!G13)=0,"","Tab") | F13: =IF(LEN('A créer'!G13)=0,"","*SAVE")
... A30: =IF(LEN('A créer'!G30)=0,"","*FN") | B30: =IF(LEN('A créer'!G30)=0,"",'A créer'!G30) | C30: =IF(LEN('A créer'!G30)=0,"","Tab") | D30: =IF(LEN('A créer'!G30)=0,IF(LEN('A créer'!G30)>0,CONCATENATE('A créer'!C30," ",'A créer'!B30),""),'A créer'!C30) | E30: =IF(LEN('A créer'!G30)=0,"","Tab") | F30: =IF(LEN('A créer'!G30)=0,"","*SAVE")

Sheet DAOPCCF_STE
A1: *FN | B1: Code | C1: Tab | D1: Description | E1: Tab 4 | F1: Tab | G1: Tab | H1: ENT | I1: Conso | J1: Tab | K1: Région | L1: DCW | M1: Tab | N1: DLS | O1: Tab | P1: DMS | Q1: Tab | R1: DRW | S1: Tab | T1: DSW | U1: Tab | V1: DEW | W1: Tab | X1: DNA | Y1: Tab | Z1: DOS | AA1: Tab | AB1: Tab | AC1: CSP | AD1: Tab | AE1: ENT | AF1: *SAVE | AG1: *FN | AH1: Code | AI1: Tab | AJ1: Description | AK1: =IF(OR('A créer'!D1="Oui",LEN('A créer'!D1)=0),"","Tab 4") -> Tab 4 | AL1: *SB | AM1: Tab | AN1: Regroup | AO1: Tab | AP1: Tab | AQ1: ENT | AR1: Conso | AS1: Tab | AT1: Région | AU1: Tab | AV1: ENT | AW1: *SAVE | AX1: *UP | AY1: *Aé | AZ1: Code | BA1: Tab | BB1: *SAVE | BC1: Close
A2: =IF(OR('A créer'!D2="Oui",LEN('A créer'!D2)=0),"","*FN") | B2: =IF(OR('A créer'!D2="Oui",LEN('A créer'!D2)=0),"",'A créer'!A2) | C2: =IF(OR('A créer'!D2="Oui",LEN('A créer'!D2)=0),"","Tab") | D2: =IF(OR('A créer'!D2="Oui",LEN('A créer'!D2)=0),"",'A créer'!C2) | E2: Tab 4 | F2: =IF(OR('A créer'!D2="Oui",LEN('A créer'!D2)=0),"","Tab") | G2: =IF(OR('A créer'!D2="Oui",LEN('A créer'!D2)=0),"","Tab") | H2: =IF(OR('A créer'!D2="Oui",LEN('A créer'!D2)=0),"","ENT") | I2: =IF(OR('A créer'!D2="Oui",LEN('A créer'!D2)=0),"","Oui") | J2: =IF(OR('A créer'!D2="Oui",LEN('A créer'!D2)=0),"","Tab") | K2: =IF(OR('A créer'!D2="Oui",LEN('A créer'!D2)=0),"",'A créer'!H2) | L2: =IF(OR('A créer'!D2="Oui",LEN('A créer'!D2)=0),"",IF($K2="DCW",'A créer'!G2,"")) | M2: =IF(OR('A créer'!D2="Oui",LEN('A créer'!D2)=0),"","Tab") | N2: =IF(OR('A créer'!D2="Oui",LEN('A créer'!D2)=0),"",IF($K2="DLS",'A créer'!G2,"")) | O2: =IF(OR('A créer'!D2="Oui",LEN('A créer'!D2)=0),"","Tab") | P2: =IF(OR('A créer'!D2="Oui",LEN('A créer'!D2)=0),"",IF($K2="DMS",'A créer'!G2,"")) | Q2: =IF(OR('A créer'!D2="Oui",LEN('A créer'!D2)=0),"","Tab") | R2: =IF(OR('A créer'!D2="Oui",LEN('A créer'!D2)=0),"",IF($K2="DRW",'A créer'!G2,"")) | S2: =IF(OR('A créer'!D2="Oui",LEN('A créer'!D2)=0),"","Tab") | T2: =IF(OR('A créer'!D2="Oui",LEN('A créer'!D2)=0),"",IF($K2="DSW",'A créer'!G2,"")) | U2: =IF(OR('A créer'!D2="Oui",LEN('A créer'!D2)=0),"","Tab") | V2: =IF(OR('A créer'!D2="Oui",LEN('A créer'!D2)=0),"",IF($K2="DEW",'A créer'!G2,"")) | W2: =IF(OR('A créer'!D2="Oui",LEN('A créer'!D2)=0),"","Tab") | X2: =IF(OR('A créer'!D2="Oui",LEN('A créer'!D2)=0),"",IF($K2="DNA",'A créer'!G2,"")) | Y2: =IF(OR('A créer'!D2="Oui",LEN('A créer'!D2)=0),"","Tab") | Z2: =IF(OR('A créer'!D2="Oui",LEN('A créer'!D2)=0),"",IF($K2="DOS",'A créer'!G2,"")) | AA2: =IF(OR('A créer'!D2="Oui",LEN('A créer'!D2)=0),"","Tab") | AB2: =IF(OR('A créer'!D2="Oui",LEN('A créer'!D2)=0),"","Tab") | AC2: =IF(OR('A créer'!D2="Oui",LEN('A créer'!D2)=0),"","OUI") | AD2: =IF(OR('A créer'!D2="Oui",LEN('A créer'!D2)=0),"","Tab") | AE2: =IF(OR('A créer'!D2="Oui",LEN('A créer'!D2)=0),"","ENT") | AF2: =IF(OR('A créer'!D2="Oui",LEN('A créer'!D2)=0),"","*SAVE") | AG2: =IF(OR('A créer'!D2="Oui",LEN('A créer'!D2)=0),"","*FN") | AH2: =IF(OR('A créer'!D2="Oui",LEN('A créer'!D2)=0),"",CONCATENATE("A",RIGHT('A créer'!A2,3))) | AI2: =IF(OR('A créer'!D2="Oui",LEN('A créer'!D2)=0),"","Tab") | AJ2: =IF(OR('A créer'!D2="Oui",LEN('A créer'!D2)=0),"",CONCATENATE('A créer'!A2," Regroupement")) | AK2: =IF(OR('A créer'!D2="Oui",LEN('A créer'!D2)=0),"","Tab 4") | AL2: =IF(OR('A créer'!D2="Oui",LEN('A créer'!D2)=0),"","*SB") | AM2: =IF(OR('A créer'!D2="Oui",LEN('A créer'!D2)=0),"","Tab") | AN2: =IF(OR('A créer'!D2="Oui",LEN('A créer'!D2)=0),"",CONCATENATE("A",'A créer'!A2)) | AO2: =IF(OR('A créer'!D2="Oui",LEN('A créer'!D2)=0),"","Tab") | AP2: =IF(OR('A créer'!D2="Oui",LEN('A créer'!D2)=0),"","Tab") | AQ2: =IF(OR('A créer'!D2="Oui",LEN('A créer'!D2)=0),"","ENT") | AR2: =IF(OR('A créer'!D2="Oui",LEN('A créer'!D2)=0),"","Non") | AS2: =IF(OR('A créer'!D2="Oui",LEN('A créer'!D2)=0),"","Tab") | AT2: =IF(OR('A créer'!D2="Oui",LEN('A créer'!D2)=0),"","T") | AU2: =IF(OR('A créer'!D2="Oui",LEN('A créer'!D2)=0),"","Tab") | AV2: =IF(OR('A créer'!D2="Oui",LEN('A créer'!D2)=0),"","ENT") | AW2: =IF(OR('A créer'!D2="Oui",LEN('A créer'!D2)=0),"","*SAVE") | AX2: =IF(OR('A créer'!D2="Oui",LEN('A créer'!D2)=0),"","*UP") | AY2: =IF(OR('A créer'!D2="Oui",LEN('A créer'!D2)=0),"","*Aé") | AZ2: =IF(OR('A créer'!D2="Oui",LEN('A créer'!D2)=0),"",'A créer'!A2) | BA2: =IF(OR('A créer'!D2="Oui",LEN('A créer'!D2)=0),"","Tab") | BB2: =IF(OR('A créer'!D2="Oui",LEN('A créer'!D2)=0),"","*SAVE") | BC2: =IF(OR('A créer'!D2="Oui",LEN('A créer'!D2)=0),"","*ML(610,125)")
A3: =IF(OR('A créer'!D3="Oui",LEN('A créer'!D3)=0),"","*FN") | B3: =IF(OR('A créer'!D3="Oui",LEN('A créer'!D3)=0),"",'A créer'!A3) | C3: =IF(OR('A créer'!D3="Oui",LEN('A créer'!D3)=0),"","Tab") | D3: =IF(OR('A créer'!D3="Oui",LEN('A créer'!D3)=0),"",'A créer'!C3) | E3: Tab 4 | F3: =IF(OR('A créer'!D3="Oui",LEN('A créer'!D3)=0),"","Tab") | G3: =IF(OR('A créer'!D3="Oui",LEN('A créer'!D3)=0),"","Tab") | H3: =IF(OR('A créer'!D3="Oui",LEN('A créer'!D3)=0),"","ENT") | I3: =IF(OR('A créer'!D3="Oui",LEN('A créer'!D3)=0),"","Oui") | J3: =IF(OR('A créer'!D3="Oui",LEN('A créer'!D3)=0),"","Tab") | K3: =IF(OR('A créer'!D3="Oui",LEN('A créer'!D3)=0),"",'A créer'!H3) | L3: =IF(OR('A créer'!D3="Oui",LEN('A créer'!D3)=0),"",IF($K3="DCW",'A créer'!G3,"")) | M3: =IF(OR('A créer'!D3="Oui",LEN('A créer'!D3)=0),"","Tab") | N3: =IF(OR('A créer'!D3="Oui",LEN('A créer'!D3)=0),"",IF($K3="DLS",'A créer'!G3,"")) | O3: =IF(OR('A créer'!D3="Oui",LEN('A créer'!D3)=0),"","Tab") | P3: =IF(OR('A créer'!D3="Oui",LEN('A créer'!D3)=0),"",IF($K3="DMS",'A créer'!G3,"")) | Q3: =IF(OR('A créer'!D3="Oui",LEN('A créer'!D3)=0),"","Tab") | R3: =IF(OR('A créer'!D3="Oui",LEN('A créer'!D3)=0),"",IF($K3="DRW",'A créer'!G3,"")) | S3: =IF(OR('A créer'!D3="Oui",LEN('A créer'!D3)=0),"","Tab") | T3: =IF(OR('A créer'!D3="Oui",LEN('A créer'!D3)=0),"",IF($K3="DSW",'A créer'!G3,"")) | U3: =IF(OR('A créer'!D3="Oui",LEN('A créer'!D3)=0),"","Tab") | V3: =IF(OR('A créer'!D3="Oui",LEN('A créer'!D3)=0),"",IF($K3="DEW",'A créer'!G3,"")) | W3: =IF(OR('A créer'!D3="Oui",LEN('A créer'!D3)=0),"","Tab") | X3: =IF(OR('A créer'!D3="Oui",LEN('A créer'!D3)=0),"",IF($K3="DNA",'A créer'!G3,"")) | Y3: =IF(OR('A créer'!D3="Oui",LEN('A créer'!D3)=0),"","Tab") | Z3: =IF(OR('A créer'!D3="Oui",LEN('A créer'!D3)=0),"",IF($K3="DOS",'A créer'!G3,"")) | AA3: =IF(OR('A créer'!D3="Oui",LEN('A créer'!D3)=0),"","Tab") | AB3: =IF(OR('A créer'!D3="Oui",LEN('A créer'!D3)=0),"","Tab") | AC3: =IF(OR('A créer'!D3="Oui",LEN('A créer'!D3)=0),"","OUI") | AD3: =IF(OR('A créer'!D3="Oui",LEN('A créer'!D3)=0),"","Tab") | AE3: =IF(OR('A créer'!D3="Oui",LEN('A créer'!D3)=0),"","ENT") | AF3: =IF(OR('A créer'!D3="Oui",LEN('A créer'!D3)=0),"","*SAVE") | AG3: =IF(OR('A créer'!D3="Oui",LEN('A créer'!D3)=0),"","*FN") | AH3: =IF(OR('A créer'!D3="Oui",LEN('A créer'!D3)=0),"",CONCATENATE("A",RIGHT('A créer'!A3,3))) | AI3: =IF(OR('A créer'!D3="Oui",LEN('A créer'!D3)=0),"","Tab") | AJ3: =IF(OR('A créer'!D3="Oui",LEN('A créer'!D3)=0),"",CONCATENATE('A créer'!A3," Regroupement")) | AK3: =IF(OR('A créer'!D3="Oui",LEN('A créer'!D3)=0),"","Tab 4") | AL3: =IF(OR('A créer'!D3="Oui",LEN('A créer'!D3)=0),"","*SB") | AM3: =IF(OR('A créer'!D3="Oui",LEN('A créer'!D3)=0),"","Tab") | AN3: =IF(OR('A créer'!D3="Oui",LEN('A créer'!D3)=0),"",CONCATENATE("A",'A créer'!A3)) | AO3: =IF(OR('A créer'!D3="Oui",LEN('A créer'!D3)=0),"","Tab") | AP3: =IF(OR('A créer'!D3="Oui",LEN('A créer'!D3)=0),"","Tab") | AQ3: =IF(OR('A créer'!D3="Oui",LEN('A créer'!D3)=0),"","ENT") | AR3: =IF(OR('A créer'!D3="Oui",LEN('A créer'!D3)=0),"","Non") | AS3: =IF(OR('A créer'!D3="Oui",LEN('A créer'!D3)=0),"","Tab") | AT3: =IF(OR('A créer'!D3="Oui",LEN('A créer'!D3)=0),"","T") | AU3: =IF(OR('A créer'!D3="Oui",LEN('A créer'!D3)=0),"","Tab") | AV3: =IF(OR('A créer'!D3="Oui",LEN('A créer'!D3)=0),"","ENT") | AW3: =IF(OR('A créer'!D3="Oui",LEN('A créer'!D3)=0),"","*SAVE") | AX3: =IF(OR('A créer'!D3="Oui",LEN('A créer'!D3)=0),"","*UP") | AY3: =IF(OR('A créer'!D3="Oui",LEN('A créer'!D3)=0),"","*Aé") | AZ3: =IF(OR('A créer'!D3="Oui",LEN('A créer'!D3)=0),"",'A créer'!A3) | BA3: =IF(OR('A créer'!D3="Oui",LEN('A créer'!D3)=0),"","Tab") | BB3: =IF(OR('A créer'!D3="Oui",LEN('A créer'!D3)=0),"","*SAVE") | BC3: =IF(OR('A créer'!D3="Oui",LEN('A créer'!D3)=0),"","*ML(610,125)")
A4: =IF(OR('A créer'!D4="Oui",LEN('A créer'!D4)=0),"","*FN") | B4: =IF(OR('A créer'!D4="Oui",LEN('A créer'!D4)=0),"",'A créer'!A4) | C4: =IF(OR('A créer'!D4="Oui",LEN('A créer'!D4)=0),"","Tab") | D4: =IF(OR('A créer'!D4="Oui",LEN('A créer'!D4)=0),"",'A créer'!C4) | E4: Tab 4 | F4: =IF(OR('A créer'!D4="Oui",LEN('A créer'!D4)=0),"","Tab") | G4: =IF(OR('A créer'!D4="Oui",LEN('A créer'!D4)=0),"","Tab") | H4: =IF(OR('A créer'!D4="Oui",LEN('A créer'!D4)=0),"","ENT") | I4: =IF(OR('A créer'!D4="Oui",LEN('A créer'!D4)=0),"","Oui") | J4: =IF(OR('A créer'!D4="Oui",LEN('A créer'!D4)=0),"","Tab") | K4: =IF(OR('A créer'!D4="Oui",LEN('A créer'!D4)=0),"",'A créer'!H4) | L4: =IF(OR('A créer'!D4="Oui",LEN('A créer'!D4)=0),"",IF($K4="DCW",'A créer'!G4,"")) | M4: =IF(OR('A créer'!D4="Oui",LEN('A créer'!D4)=0),"","Tab") | N4: =IF(OR('A créer'!D4="Oui",LEN('A créer'!D4)=0),"",IF($K4="DLS",'A créer'!G4,"")) | O4: =IF(OR('A créer'!D4="Oui",LEN('A créer'!D4)=0),"","Tab") | P4: =IF(OR('A créer'!D4="Oui",LEN('A créer'!D4)=0),"",IF($K4="DMS",'A créer'!G4,"")) | Q4: =IF(OR('A créer'!D4="Oui",LEN('A créer'!D4)=0),"","Tab") | R4: =IF(OR('A créer'!D4="Oui",LEN('A créer'!D4)=0),"",IF($K4="DRW",'A créer'!G4,"")) | S4: =IF(OR('A créer'!D4="Oui",LEN('A créer'!D4)=0),"","Tab") | T4: =IF(OR('A créer'!D4="Oui",LEN('A créer'!D4)=0),"",IF($K4="DSW",'A créer'!G4,"")) | U4: =IF(OR('A créer'!D4="Oui",LEN('A créer'!D4)=0),"","Tab") | V4: =IF(OR('A créer'!D4="Oui",LEN('A créer'!D4)=0),"",IF($K4="DEW",'A créer'!G4,"")) | W4: =IF(OR('A créer'!D4="Oui",LEN('A créer'!D4)=0),"","Tab") | X4: =IF(OR('A créer'!D4="Oui",LEN('A créer'!D4)=0),"",IF($K4="DNA",'A créer'!G4,"")) | Y4: =IF(OR('A créer'!D4="Oui",LEN('A créer'!D4)=0),"","Tab") | Z4: =IF(OR('A créer'!D4="Oui",LEN('A créer'!D4)=0),"",IF($K4="DOS",'A créer'!G4,"")) | AA4: =IF(OR('A créer'!D4="Oui",LEN('A créer'!D4)=0),"","Tab") | AB4: =IF(OR('A créer'!D4="Oui",LEN('A créer'!D4)=0),"","Tab") | AC4: =IF(OR('A créer'!D4="Oui",LEN('A créer'!D4)=0),"","OUI") | AD4: =IF(OR('A créer'!D4="Oui",LEN('A créer'!D4)=0),"","Tab") | AE4: =IF(OR('A créer'!D4="Oui",LEN('A créer'!D4)=0),"","ENT") | AF4: =IF(OR('A créer'!D4="Oui",LEN('A créer'!D4)=0),"","*SAVE") | AG4: =IF(OR('A créer'!D4="Oui",LEN('A créer'!D4)=0),"","*FN") | AH4: =IF(OR('A créer'!D4="Oui",LEN('A créer'!D4)=0),"",CONCATENATE("A",RIGHT('A créer'!A4,3))) | AI4: =IF(OR('A créer'!D4="Oui",LEN('A créer'!D4)=0),"","Tab") | AJ4: =IF(OR('A créer'!D4="Oui",LEN('A créer'!D4)=0),"",CONCATENATE('A créer'!A4," Regroupement")) | AK4: =IF(OR('A créer'!D4="Oui",LEN('A créer'!D4)=0),"","Tab 4") | AL4: =IF(OR('A créer'!D4="Oui",LEN('A créer'!D4)=0),"","*SB") | AM4: =IF(OR('A créer'!D4="Oui",LEN('A créer'!D4)=0),"","Tab") | AN4: =IF(OR('A créer'!D4="Oui",LEN('A créer'!D4)=0),"",CONCATENATE("A",'A créer'!A4)) | AO4: =IF(OR('A créer'!D4="Oui",LEN('A créer'!D4)=0),"","Tab") | AP4: =IF(OR('A créer'!D4="Oui",LEN('A créer'!D4)=0),"","Tab") | AQ4: =IF(OR('A créer'!D4="Oui",LEN('A créer'!D4)=0),"","ENT") | AR4: =IF(OR('A créer'!D4="Oui",LEN('A créer'!D4)=0),"","Non") | AS4: =IF(OR('A créer'!D4="Oui",LEN('A créer'!D4)=0),"","Tab") | AT4: =IF(OR('A créer'!D4="Oui",LEN('A créer'!D4)=0),"","T") | AU4: =IF(OR('A créer'!D4="Oui",LEN('A créer'!D4)=0),"","Tab") | AV4: =IF(OR('A créer'!D4="Oui",LEN('A créer'!D4)=0),"","ENT") | AW4: =IF(OR('A créer'!D4="Oui",LEN('A créer'!D4)=0),"","*SAVE") | AX4: =IF(OR('A créer'!D4="Oui",LEN('A créer'!D4)=0),"","*UP") | AY4: =IF(OR('A créer'!D4="Oui",LEN('A créer'!D4)=0),"","*Aé") | AZ4: =IF(OR('A créer'!D4="Oui",LEN('A créer'!D4)=0),"",'A créer'!A4) | BA4: =IF(OR('A créer'!D4="Oui",LEN('A créer'!D4)=0),"","Tab") | BB4: =IF(OR('A créer'!D4="Oui",LEN('A créer'!D4)=0),"","*SAVE") | BC4: =IF(OR('A créer'!D4="Oui",LEN('A créer'!D4)=0),"","*ML(610,125)")
A5: =IF(OR('A créer'!D5="Oui",LEN('A créer'!D5)=0),"","*FN") | B5: =IF(OR('A créer'!D5="Oui",LEN('A créer'!D5)=0),"",'A créer'!A5) | C5: =IF(OR('A créer'!D5="Oui",LEN('A créer'!D5)=0),"","Tab") | D5: =IF(OR('A créer'!D5="Oui",LEN('A créer'!D5)=0),"",'A créer'!C5) | E5: Tab 4 | F5: =IF(OR('A créer'!D5="Oui",LEN('A créer'!D5)=0),"","Tab") | G5: =IF(OR('A créer'!D5="Oui",LEN('A créer'!D5)=0),"","Tab") | H5: =IF(OR('A créer'!D5="Oui",LEN('A créer'!D5)=0),"","ENT") | I5: =IF(OR('A créer'!D5="Oui",LEN('A créer'!D5)=0),"","Oui") | J5: =IF(OR('A créer'!D5="Oui",LEN('A créer'!D5)=0),"","Tab") | K5: =IF(OR('A créer'!D5="Oui",LEN('A créer'!D5)=0),"",'A créer'!H5) | L5: =IF(OR('A créer'!D5="Oui",LEN('A créer'!D5)=0),"",IF($K5="DCW",'A créer'!G5,"")) | M5: =IF(OR('A créer'!D5="Oui",LEN('A créer'!D5)=0),"","Tab") | N5: =IF(OR('A créer'!D5="Oui",LEN('A créer'!D5)=0),"",IF($K5="DLS",'A créer'!G5,"")) | O5: =IF(OR('A créer'!D5="Oui",LEN('A créer'!D5)=0),"","Tab") | P5: =IF(OR('A créer'!D5="Oui",LEN('A créer'!D5)=0),"",IF($K5="DMS",'A créer'!G5,"")) | Q5: =IF(OR('A créer'!D5="Oui",LEN('A créer'!D5)=0),"","Tab") | R5: =IF(OR('A créer'!D5="Oui",LEN('A créer'!D5)=0),"",IF($K5="DRW",'A créer'!G5,"")) | S5: =IF(OR('A créer'!D5="Oui",LEN('A créer'!D5)=0),"","Tab") | T5: =IF(OR('A créer'!D5="Oui",LEN('A créer'!D5)=0),"",IF($K5="DSW",'A créer'!G5,"")) | U5: =IF(OR('A créer'!D5="Oui",LEN('A créer'!D5)=0),"","Tab") | V5: =IF(OR('A créer'!D5="Oui",LEN('A créer'!D5)=0),"",IF($K5="DEW",'A créer'!G5,"")) | W5: =IF(OR('A créer'!D5="Oui",LEN('A créer'!D5)=0),"","Tab") | X5: =IF(OR('A créer'!D5="Oui",LEN('A créer'!D5)=0),"",IF($K5="DNA",'A créer'!G5,"")) | Y5: =IF(OR('A créer'!D5="Oui",LEN('A créer'!D5)=0),"","Tab") | Z5: =IF(OR('A créer'!D5="Oui",LEN('A créer'!D5)=0),"",IF($K5="DOS",'A créer'!G5,"")) | AA5: =IF(OR('A créer'!D5="Oui",LEN('A créer'!D5)=0),"","Tab") | AB5: =IF(OR('A créer'!D5="Oui",LEN('A créer'!D5)=0),"","Tab") | AC5: =IF(OR('A créer'!D5="Oui",LEN('A créer'!D5)=0),"","OUI") | AD5: =IF(OR('A créer'!D5="Oui",LEN('A créer'!D5)=0),"","Tab") | AE5: =IF(OR('A créer'!D5="Oui",LEN('A créer'!D5)=0),"","ENT") | AF5: =IF(OR('A créer'!D5="Oui",LEN('A créer'!D5)=0),"","*SAVE") | AG5: =IF(OR('A créer'!D5="Oui",LEN('A créer'!D5)=0),"","*FN") | AH5: =IF(OR('A créer'!D5="Oui",LEN('A créer'!D5)=0),"",CONCATENATE("A",RIGHT('A créer'!A5,3))) | AI5: =IF(OR('A créer'!D5="Oui",LEN('A créer'!D5)=0),"","Tab") | AJ5: =IF(OR('A créer'!D5="Oui",LEN('A créer'!D5)=0),"",CONCATENATE('A créer'!A5," Regroupement")) | AK5: =IF(OR('A créer'!D5="Oui",LEN('A créer'!D5)=0),"","Tab 4") | AL5: =IF(OR('A créer'!D5="Oui",LEN('A créer'!D5)=0),"","*SB") | AM5: =IF(OR('A créer'!D5="Oui",LEN('A créer'!D5)=0),"","Tab") | AN5: =IF(OR('A créer'!D5="Oui",LEN('A créer'!D5)=0),"",CONCATENATE("A",'A créer'!A5)) | AO5: =IF(OR('A créer'!D5="Oui",LEN('A créer'!D5)=0),"","Tab") | AP5: =IF(OR('A créer'!D5="Oui",LEN('A créer'!D5)=0),"","Tab") | AQ5: =IF(OR('A créer'!D5="Oui",LEN('A créer'!D5)=0),"","ENT") | AR5: =IF(OR('A créer'!D5="Oui",LEN('A créer'!D5)=0),"","Non") | AS5: =IF(OR('A créer'!D5="Oui",LEN('A créer'!D5)=0),"","Tab") | AT5: =IF(OR('A créer'!D5="Oui",LEN('A créer'!D5)=0),"","T") | AU5: =IF(OR('A créer'!D5="Oui",LEN('A créer'!D5)=0),"","Tab") | AV5: =IF(OR('A créer'!D5="Oui",LEN('A créer'!D5)=0),"","ENT") | AW5: =IF(OR('A créer'!D5="Oui",LEN('A créer'!D5)=0),"","*SAVE") | AX5: =IF(OR('A créer'!D5="Oui",LEN('A créer'!D5)=0),"","*UP") | AY5: =IF(OR('A créer'!D5="Oui",LEN('A créer'!D5)=0),"","*Aé") | AZ5: =IF(OR('A créer'!D5="Oui",LEN('A créer'!D5)=0),"",'A créer'!A5) | BA5: =IF(OR('A créer'!D5="Oui",LEN('A créer'!D5)=0),"","Tab") | BB5: =IF(OR('A créer'!D5="Oui",LEN('A créer'!D5)=0),"","*SAVE") | BC5: =IF(OR('A créer'!D5="Oui",LEN('A créer'!D5)=0),"","*ML(610,125)")
A6: =IF(OR('A créer'!D6="Oui",LEN('A créer'!D6)=0),"","*FN") -> *FN | B6: =IF(OR('A créer'!D6="Oui",LEN('A créer'!D6)=0),"",'A créer'!A6) -> 0401 | C6: =IF(OR('A créer'!D6="Oui",LEN('A créer'!D6)=0),"","Tab") -> Tab | D6: =IF(OR('A créer'!D6="Oui",LEN('A créer'!D6)=0),"",'A créer'!C6) -> SOCIETE VALMY DEFENSE 101 | E6: Tab 4 | F6: =IF(OR('A créer'!D6="Oui",LEN('A créer'!D6)=0),"","Tab") -> Tab | G6: =IF(OR('A créer'!D6="Oui",LEN('A créer'!D6)=0),"","Tab") -> Tab | H6: =IF(OR('A créer'!D6="Oui",LEN('A créer'!D6)=0),"","ENT") -> ENT | I6: =IF(OR('A créer'!D6="Oui",LEN('A créer'!D6)=0),"","Oui") -> Oui | J6: =IF(OR('A créer'!D6="Oui",LEN('A créer'!D6)=0),"","Tab") -> Tab | K6: =IF(OR('A créer'!D6="Oui",LEN('A créer'!D6)=0),"",'A créer'!H6) -> DRW | L6: =IF(OR('A créer'!D6="Oui",LEN('A créer'!D6)=0),"",IF($K6="DCW",'A créer'!G6,"")) | M6: =IF(OR('A créer'!D6="Oui",LEN('A créer'!D6)=0),"","Tab") -> Tab | N6: =IF(OR('A créer'!D6="Oui",LEN('A créer'!D6)=0),"",IF($K6="DLS",'A créer'!G6,"")) | O6: =IF(OR('A créer'!D6="Oui",LEN('A créer'!D6)=0),"","Tab") -> Tab | P6: =IF(OR('A créer'!D6="Oui",LEN('A créer'!D6)=0),"",IF($K6="DMS",'A créer'!G6,"")) | Q6: =IF(OR('A créer'!D6="Oui",LEN('A créer'!D6)=0),"","Tab") -> Tab | R6: =IF(OR('A créer'!D6="Oui",LEN('A créer'!D6)=0),"",IF($K6="DRW",'A créer'!G6,"")) -> S0101 | S6: =IF(OR('A créer'!D6="Oui",LEN('A créer'!D6)=0),"","Tab") -> Tab | T6: =IF(OR('A créer'!D6="Oui",LEN('A créer'!D6)=0),"",IF($K6="DSW",'A créer'!G6,"")) | U6: =IF(OR('A créer'!D6="Oui",LEN('A créer'!D6)=0),"","Tab") -> Tab | V6: =IF(OR('A créer'!D6="Oui",LEN('A créer'!D6)=0),"",IF($K6="DEW",'A créer'!G6,"")) | W6: =IF(OR('A créer'!D6="Oui",LEN('A créer'!D6)=0),"","Tab") -> Tab | X6: =IF(OR('A créer'!D6="Oui",LEN('A créer'!D6)=0),"",IF($K6="DNA",'A créer'!G6,"")) | Y6: =IF(OR('A créer'!D6="Oui",LEN('A créer'!D6)=0),"","Tab") -> Tab | Z6: =IF(OR('A créer'!D6="Oui",LEN('A créer'!D6)=0),"",IF($K6="DOS",'A créer'!G6,"")) | AA6: =IF(OR('A créer'!D6="Oui",LEN('A créer'!D6)=0),"","Tab") -> Tab | AB6: =IF(OR('A créer'!D6="Oui",LEN('A créer'!D6)=0),"","Tab") -> Tab | AC6: =IF(OR('A créer'!D6="Oui",LEN('A créer'!D6)=0),"","OUI") -> OUI | AD6: =IF(OR('A créer'!D6="Oui",LEN('A créer'!D6)=0),"","Tab") -> Tab | AE6: =IF(OR('A créer'!D6="Oui",LEN('A créer'!D6)=0),"","ENT") -> ENT | AF6: =IF(OR('A créer'!D6="Oui",LEN('A créer'!D6)=0),"","*SAVE") -> *SAVE | AG6: =IF(OR('A créer'!D6="Oui",LEN('A créer'!D6)=0),"","*FN") -> *FN | AH6: =IF(OR('A créer'!D6="Oui",LEN('A créer'!D6)=0),"",CONCATENATE("A",RIGHT('A créer'!A6,3))) -> A401 | AI6: =IF(OR('A créer'!D6="Oui",LEN('A créer'!D6)=0),"","Tab") -> Tab | AJ6: =IF(OR('A créer'!D6="Oui",LEN('A créer'!D6)=0),"",CONCATENATE('A créer'!A6," Regroupement")) -> 0401 Regroupement | AK6: =IF(OR('A créer'!D6="Oui",LEN('A créer'!D6)=0),"","Tab 4") -> Tab 4 | AL6: =IF(OR('A créer'!D6="Oui",LEN('A créer'!D6)=0),"","*SB") -> *SB | AM6: =IF(OR('A créer'!D6="Oui",LEN('A créer'!D6)=0),"","Tab") -> Tab | AN6: =IF(OR('A créer'!D6="Oui",LEN('A créer'!D6)=0),"",CONCATENATE("A",'A créer'!A6)) -> A0401 | AO6: =IF(OR('A créer'!D6="Oui",LEN('A créer'!D6)=0),"","Tab") -> Tab | AP6: =IF(OR('A créer'!D6="Oui",LEN('A créer'!D6)=0),"","Tab") -> Tab | AQ6: =IF(OR('A créer'!D6="Oui",LEN('A créer'!D6)=0),"","ENT") -> ENT | AR6: =IF(OR('A créer'!D6="Oui",LEN('A créer'!D6)=0),"","Non") -> Non | AS6: =IF(OR('A créer'!D6="Oui",LEN('A créer'!D6)=0),"","Tab") -> Tab | AT6: =IF(OR('A créer'!D6="Oui",LEN('A créer'!D6)=0),"","T") -> T | AU6: =IF(OR('A créer'!D6="Oui",LEN('A créer'!D6)=0),"","Tab") -> Tab | AV6: =IF(OR('A créer'!D6="Oui",LEN('A créer'!D6)=0),"","ENT") -> ENT | AW6: =IF(OR('A créer'!D6="Oui",LEN('A créer'!D6)=0),"","*SAVE") -> *SAVE | AX6: =IF(OR('A créer'!D6="Oui",LEN('A créer'!D6)=0),"","*UP") -> *UP | AY6: =IF(OR('A créer'!D6="Oui",LEN('A créer'!D6)=0),"","*Aé") -> *Aé | AZ6: =IF(OR('A créer'!D6="Oui",LEN('A créer'!D6)=0),"",'A créer'!A6) -> 0401 | BA6: =IF(OR('A créer'!D6="Oui",LEN('A créer'!D6)=0),"","Tab") -> Tab | BB6: =IF(OR('A créer'!D6="Oui",LEN('A créer'!D6)=0),"","*SAVE") -> *SAVE | BC6: =IF(OR('A créer'!D6="Oui",LEN('A créer'!D6)=0),"","*ML(610,125)") -> *ML(610,125)
A7: =IF(OR('A créer'!D7="Oui",LEN('A créer'!D7)=0),"","*FN") | B7: =IF(OR('A créer'!D7="Oui",LEN('A créer'!D7)=0),"",'A créer'!A7) | C7: =IF(OR('A créer'!D7="Oui",LEN('A créer'!D7)=0),"","Tab") | D7: =IF(OR('A créer'!D7="Oui",LEN('A créer'!D7)=0),"",'A créer'!C7) | E7: Tab 4 | F7: =IF(OR('A créer'!D7="Oui",LEN('A créer'!D7)=0),"","Tab") | G7: =IF(OR('A créer'!D7="Oui",LEN('A créer'!D7)=0),"","Tab") | H7: =IF(OR('A créer'!D7="Oui",LEN('A créer'!D7)=0),"","ENT") | I7: =IF(OR('A créer'!D7="Oui",LEN('A créer'!D7)=0),"","Oui") | J7: =IF(OR('A créer'!D7="Oui",LEN('A créer'!D7)=0),"","Tab") | K7: =IF(OR('A créer'!D7="Oui",LEN('A créer'!D7)=0),"",'A créer'!H7) | L7: =IF(OR('A créer'!D7="Oui",LEN('A créer'!D7)=0),"",IF($K7="DCW",'A créer'!G7,"")) | M7: =IF(OR('A créer'!D7="Oui",LEN('A créer'!D7)=0),"","Tab") | N7: =IF(OR('A créer'!D7="Oui",LEN('A créer'!D7)=0),"",IF($K7="DLS",'A créer'!G7,"")) | O7: =IF(OR('A créer'!D7="Oui",LEN('A créer'!D7)=0),"","Tab") | P7: =IF(OR('A créer'!D7="Oui",LEN('A créer'!D7)=0),"",IF($K7="DMS",'A créer'!G7,"")) | Q7: =IF(OR('A créer'!D7="Oui",LEN('A créer'!D7)=0),"","Tab") | R7: =IF(OR('A créer'!D7="Oui",LEN('A créer'!D7)=0),"",IF($K7="DRW",'A créer'!G7,"")) | S7: =IF(OR('A créer'!D7="Oui",LEN('A créer'!D7)=0),"","Tab") | T7: =IF(OR('A créer'!D7="Oui",LEN('A créer'!D7)=0),"",IF($K7="DSW",'A créer'!G7,"")) | U7: =IF(OR('A créer'!D7="Oui",LEN('A créer'!D7)=0),"","Tab") | V7: =IF(OR('A créer'!D7="Oui",LEN('A créer'!D7)=0),"",IF($K7="DEW",'A créer'!G7,"")) | W7: =IF(OR('A créer'!D7="Oui",LEN('A créer'!D7)=0),"","Tab") | X7: =IF(OR('A créer'!D7="Oui",LEN('A créer'!D7)=0),"",IF($K7="DNA",'A créer'!G7,"")) | Y7: =IF(OR('A créer'!D7="Oui",LEN('A créer'!D7)=0),"","Tab") | Z7: =IF(OR('A créer'!D7="Oui",LEN('A créer'!D7)=0),"",IF($K7="DOS",'A créer'!G7,"")) | AA7: =IF(OR('A créer'!D7="Oui",LEN('A créer'!D7)=0),"","Tab") | AB7: =IF(OR('A créer'!D7="Oui",LEN('A créer'!D7)=0),"","Tab") | AC7: =IF(OR('A créer'!D7="Oui",LEN('A créer'!D7)=0),"","OUI") | AD7: =IF(OR('A créer'!D7="Oui",LEN('A créer'!D7)=0),"","Tab") | AE7: =IF(OR('A créer'!D7="Oui",LEN('A créer'!D7)=0),"","ENT") | AF7: =IF(OR('A créer'!D7="Oui",LEN('A créer'!D7)=0),"","*SAVE") | AG7: =IF(OR('A créer'!D7="Oui",LEN('A créer'!D7)=0),"","*FN") | AH7: =IF(OR('A créer'!D7="Oui",LEN('A créer'!D7)=0),"",CONCATENATE("A",RIGHT('A créer'!A7,3))) | AI7: =IF(OR('A créer'!D7="Oui",LEN('A créer'!D7)=0),"","Tab") | AJ7: =IF(OR('A créer'!D7="Oui",LEN('A créer'!D7)=0),"",CONCATENATE('A créer'!A7," Regroupement")) | AK7: =IF(OR('A créer'!D7="Oui",LEN('A créer'!D7)=0),"","Tab 4") | AL7: =IF(OR('A créer'!D7="Oui",LEN('A créer'!D7)=0),"","*SB") | AM7: =IF(OR('A créer'!D7="Oui",LEN('A créer'!D7)=0),"","Tab") | AN7: =IF(OR('A créer'!D7="Oui",LEN('A créer'!D7)=0),"",CONCATENATE("A",'A créer'!A7)) | AO7: =IF(OR('A créer'!D7="Oui",LEN('A créer'!D7)=0),"","Tab") | AP7: =IF(OR('A créer'!D7="Oui",LEN('A créer'!D7)=0),"","Tab") | AQ7: =IF(OR('A créer'!D7="Oui",LEN('A créer'!D7)=0),"","ENT") | AR7: =IF(OR('A créer'!D7="Oui",LEN('A créer'!D7)=0),"","Non") | AS7: =IF(OR('A créer'!D7="Oui",LEN('A créer'!D7)=0),"","Tab") | AT7: =IF(OR('A créer'!D7="Oui",LEN('A créer'!D7)=0),"","T") | AU7: =IF(OR('A créer'!D7="Oui",LEN('A créer'!D7)=0),"","Tab") | AV7: =IF(OR('A créer'!D7="Oui",LEN('A créer'!D7)=0),"","ENT") | AW7: =IF(OR('A créer'!D7="Oui",LEN('A créer'!D7)=0),"","*SAVE") | AX7: =IF(OR('A créer'!D7="Oui",LEN('A créer'!D7)=0),"","*UP") | AY7: =IF(OR('A créer'!D7="Oui",LEN('A créer'!D7)=0),"","*Aé") | AZ7: =IF(OR('A créer'!D7="Oui",LEN('A créer'!D7)=0),"",'A créer'!A7) | BA7: =IF(OR('A créer'!D7="Oui",LEN('A créer'!D7)=0),"","Tab") | BB7: =IF(OR('A créer'!D7="Oui",LEN('A créer'!D7)=0),"","*SAVE") | BC7: =IF(OR('A créer'!D7="Oui",LEN('A créer'!D7)=0),"","*ML(610,125)")
A8: =IF(OR('A créer'!D8="Oui",LEN('A créer'!D8)=0),"","*FN") | B8: =IF(OR('A créer'!D8="Oui",LEN('A créer'!D8)=0),"",'A créer'!A8) | C8: =IF(OR('A créer'!D8="Oui",LEN('A créer'!D8)=0),"","Tab") | D8: =IF(OR('A créer'!D8="Oui",LEN('A créer'!D8)=0),"",'A créer'!C8) | E8: Tab 4 | F8: =IF(OR('A créer'!D8="Oui",LEN('A créer'!D8)=0),"","Tab") | G8: =IF(OR('A créer'!D8="Oui",LEN('A créer'!D8)=0),"","Tab") | H8: =IF(OR('A créer'!D8="Oui",LEN('A créer'!D8)=0),"","ENT") | I8: =IF(OR('A créer'!D8="Oui",LEN('A créer'!D8)=0),"","Oui") | J8: =IF(OR('A créer'!D8="Oui",LEN('A créer'!D8)=0),"","Tab") | K8: =IF(OR('A créer'!D8="Oui",LEN('A créer'!D8)=0),"",'A créer'!H8) | L8: =IF(OR('A créer'!D8="Oui",LEN('A créer'!D8)=0),"",IF($K8="DCW",'A créer'!G8,"")) | M8: =IF(OR('A créer'!D8="Oui",LEN('A créer'!D8)=0),"","Tab") | N8: =IF(OR('A créer'!D8="Oui",LEN('A créer'!D8)=0),"",IF($K8="DLS",'A créer'!G8,"")) | O8: =IF(OR('A créer'!D8="Oui",LEN('A créer'!D8)=0),"","Tab") | P8: =IF(OR('A créer'!D8="Oui",LEN('A créer'!D8)=0),"",IF($K8="DMS",'A créer'!G8,"")) | Q8: =IF(OR('A créer'!D8="Oui",LEN('A créer'!D8)=0),"","Tab") | R8: =IF(OR('A créer'!D8="Oui",LEN('A créer'!D8)=0),"",IF($K8="DRW",'A créer'!G8,"")) | S8: =IF(OR('A créer'!D8="Oui",LEN('A créer'!D8)=0),"","Tab") | T8: =IF(OR('A créer'!D8="Oui",LEN('A créer'!D8)=0),"",IF($K8="DSW",'A créer'!G8,"")) | U8: =IF(OR('A créer'!D8="Oui",LEN('A créer'!D8)=0),"","Tab") | V8: =IF(OR('A créer'!D8="Oui",LEN('A créer'!D8)=0),"",IF($K8="DEW",'A créer'!G8,"")) | W8: =IF(OR('A créer'!D8="Oui",LEN('A créer'!D8)=0),"","Tab") | X8: =IF(OR('A créer'!D8="Oui",LEN('A créer'!D8)=0),"",IF($K8="DNA",'A créer'!G8,"")) | Y8: =IF(OR('A créer'!D8="Oui",LEN('A créer'!D8)=0),"","Tab") | Z8: =IF(OR('A créer'!D8="Oui",LEN('A créer'!D8)=0),"",IF($K8="DOS",'A créer'!G8,"")) | AA8: =IF(OR('A créer'!D8="Oui",LEN('A créer'!D8)=0),"","Tab") | AB8: =IF(OR('A créer'!D8="Oui",LEN('A créer'!D8)=0),"","Tab") | AC8: =IF(OR('A créer'!D8="Oui",LEN('A créer'!D8)=0),"","OUI") | AD8: =IF(OR('A créer'!D8="Oui",LEN('A créer'!D8)=0),"","Tab") | AE8: =IF(OR('A créer'!D8="Oui",LEN('A créer'!D8)=0),"","ENT") | AF8: =IF(OR('A créer'!D8="Oui",LEN('A créer'!D8)=0),"","*SAVE") | AG8: =IF(OR('A créer'!D8="Oui",LEN('A créer'!D8)=0),"","*FN") | AH8: =IF(OR('A créer'!D8="Oui",LEN('A créer'!D8)=0),"",CONCATENATE("A",RIGHT('A créer'!A8,3))) | AI8: =IF(OR('A créer'!D8="Oui",LEN('A créer'!D8)=0),"","Tab") | AJ8: =IF(OR('A créer'!D8="Oui",LEN('A créer'!D8)=0),"",CONCATENATE('A créer'!A8," Regroupement")) | AK8: =IF(OR('A créer'!D8="Oui",LEN('A créer'!D8)=0),"","Tab 4") | AL8: =IF(OR('A créer'!D8="Oui",LEN('A créer'!D8)=0),"","*SB") | AM8: =IF(OR('A créer'!D8="Oui",LEN('A créer'!D8)=0),"","Tab") | AN8: =IF(OR('A créer'!D8="Oui",LEN('A créer'!D8)=0),"",CONCATENATE("A",'A créer'!A8)) | AO8: =IF(OR('A créer'!D8="Oui",LEN('A créer'!D8)=0),"","Tab") | AP8: =IF(OR('A créer'!D8="Oui",LEN('A créer'!D8)=0),"","Tab") | AQ8: =IF(OR('A créer'!D8="Oui",LEN('A créer'!D8)=0),"","ENT") | AR8: =IF(OR('A créer'!D8="Oui",LEN('A créer'!D8)=0),"","Non") | AS8: =IF(OR('A créer'!D8="Oui",LEN('A créer'!D8)=0),"","Tab") | AT8: =IF(OR('A créer'!D8="Oui",LEN('A créer'!D8)=0),"","T") | AU8: =IF(OR('A créer'!D8="Oui",LEN('A créer'!D8)=0),"","Tab") | AV8: =IF(OR('A créer'!D8="Oui",LEN('A créer'!D8)=0),"","ENT") | AW8: =IF(OR('A créer'!D8="Oui",LEN('A créer'!D8)=0),"","*SAVE") | AX8: =IF(OR('A créer'!D8="Oui",LEN('A créer'!D8)=0),"","*UP") | AY8: =IF(OR('A créer'!D8="Oui",LEN('A créer'!D8)=0),"","*Aé") | AZ8: =IF(OR('A créer'!D8="Oui",LEN('A créer'!D8)=0),"",'A créer'!A8) | BA8: =IF(OR('A créer'!D8="Oui",LEN('A créer'!D8)=0),"","Tab") | BB8: =IF(OR('A créer'!D8="Oui",LEN('A créer'!D8)=0),"","*SAVE") | BC8: =IF(OR('A créer'!D8="Oui",LEN('A créer'!D8)=0),"","*ML(610,125)")
A9: =IF(OR('A créer'!D9="Oui",LEN('A créer'!D9)=0),"","*FN") | B9: =IF(OR('A créer'!D9="Oui",LEN('A créer'!D9)=0),"",'A créer'!A9) | C9: =IF(OR('A créer'!D9="Oui",LEN('A créer'!D9)=0),"","Tab") | D9: =IF(OR('A créer'!D9="Oui",LEN('A créer'!D9)=0),"",'A créer'!C9) | E9: Tab 4 | F9: =IF(OR('A créer'!D9="Oui",LEN('A créer'!D9)=0),"","Tab") | G9: =IF(OR('A créer'!D9="Oui",LEN('A créer'!D9)=0),"","Tab") | H9: =IF(OR('A créer'!D9="Oui",LEN('A créer'!D9)=0),"","ENT") | I9: =IF(OR('A créer'!D9="Oui",LEN('A créer'!D9)=0),"","Oui") | J9: =IF(OR('A créer'!D9="Oui",LEN('A créer'!D9)=0),"","Tab") | K9: =IF(OR('A créer'!D9="Oui",LEN('A créer'!D9)=0),"",'A créer'!H9) | L9: =IF(OR('A créer'!D9="Oui",LEN('A créer'!D9)=0),"",IF($K9="DCW",'A créer'!G9,"")) | M9: =IF(OR('A créer'!D9="Oui",LEN('A créer'!D9)=0),"","Tab") | N9: =IF(OR('A créer'!D9="Oui",LEN('A créer'!D9)=0),"",IF($K9="DLS",'A créer'!G9,"")) | O9: =IF(OR('A créer'!D9="Oui",LEN('A créer'!D9)=0),"","Tab") | P9: =IF(OR('A créer'!D9="Oui",LEN('A créer'!D9)=0),"",IF($K9="DMS",'A créer'!G9,"")) | Q9: =IF(OR('A créer'!D9="Oui",LEN('A créer'!D9)=0),"","Tab") | R9: =IF(OR('A créer'!D9="Oui",LEN('A créer'!D9)=0),"",IF($K9="DRW",'A créer'!G9,"")) | S9: =IF(OR('A créer'!D9="Oui",LEN('A créer'!D9)=0),"","Tab") | T9: =IF(OR('A créer'!D9="Oui",LEN('A créer'!D9)=0),"",IF($K9="DSW",'A créer'!G9,"")) | U9: =IF(OR('A créer'!D9="Oui",LEN('A créer'!D9)=0),"","Tab") | V9: =IF(OR('A créer'!D9="Oui",LEN('A créer'!D9)=0),"",IF($K9="DEW",'A créer'!G9,"")) | W9: =IF(OR('A créer'!D9="Oui",LEN('A créer'!D9)=0),"","Tab") | X9: =IF(OR('A créer'!D9="Oui",LEN('A créer'!D9)=0),"",IF($K9="DNA",'A créer'!G9,"")) | Y9: =IF(OR('A créer'!D9="Oui",LEN('A créer'!D9)=0),"","Tab") | Z9: =IF(OR('A créer'!D9="Oui",LEN('A créer'!D9)=0),"",IF($K9="DOS",'A créer'!G9,"")) | AA9: =IF(OR('A créer'!D9="Oui",LEN('A créer'!D9)=0),"","Tab") | AB9: =IF(OR('A créer'!D9="Oui",LEN('A créer'!D9)=0),"","Tab") | AC9: =IF(OR('A créer'!D9="Oui",LEN('A créer'!D9)=0),"","OUI") | AD9: =IF(OR('A créer'!D9="Oui",LEN('A créer'!D9)=0),"","Tab") | AE9: =IF(OR('A créer'!D9="Oui",LEN('A créer'!D9)=0),"","ENT") | AF9: =IF(OR('A créer'!D9="Oui",LEN('A créer'!D9)=0),"","*SAVE") | AG9: =IF(OR('A créer'!D9="Oui",LEN('A créer'!D9)=0),"","*FN") | AH9: =IF(OR('A créer'!D9="Oui",LEN('A créer'!D9)=0),"",CONCATENATE("A",RIGHT('A créer'!A9,3))) | AI9: =IF(OR('A créer'!D9="Oui",LEN('A créer'!D9)=0),"","Tab") | AJ9: =IF(OR('A créer'!D9="Oui",LEN('A créer'!D9)=0),"",CONCATENATE('A créer'!A9," Regroupement")) | AK9: =IF(OR('A créer'!D9="Oui",LEN('A créer'!D9)=0),"","Tab 4") | AL9: =IF(OR('A créer'!D9="Oui",LEN('A créer'!D9)=0),"","*SB") | AM9: =IF(OR('A créer'!D9="Oui",LEN('A créer'!D9)=0),"","Tab") | AN9: =IF(OR('A créer'!D9="Oui",LEN('A créer'!D9)=0),"",CONCATENATE("A",'A créer'!A9)) | AO9: =IF(OR('A créer'!D9="Oui",LEN('A créer'!D9)=0),"","Tab") | AP9: =IF(OR('A créer'!D9="Oui",LEN('A créer'!D9)=0),"","Tab") | AQ9: =IF(OR('A créer'!D9="Oui",LEN('A créer'!D9)=0),"","ENT") | AR9: =IF(OR('A créer'!D9="Oui",LEN('A créer'!D9)=0),"","Non") | AS9: =IF(OR('A créer'!D9="Oui",LEN('A créer'!D9)=0),"","Tab") | AT9: =IF(OR('A créer'!D9="Oui",LEN('A créer'!D9)=0),"","T") | AU9: =IF(OR('A créer'!D9="Oui",LEN('A créer'!D9)=0),"","Tab") | AV9: =IF(OR('A créer'!D9="Oui",LEN('A créer'!D9)=0),"","ENT") | AW9: =IF(OR('A créer'!D9="Oui",LEN('A créer'!D9)=0),"","*SAVE") | AX9: =IF(OR('A créer'!D9="Oui",LEN('A créer'!D9)=0),"","*UP") | AY9: =IF(OR('A créer'!D9="Oui",LEN('A créer'!D9)=0),"","*Aé") | AZ9: =IF(OR('A créer'!D9="Oui",LEN('A créer'!D9)=0),"",'A créer'!A9) | BA9: =IF(OR('A créer'!D9="Oui",LEN('A créer'!D9)=0),"","Tab") | BB9: =IF(OR('A créer'!D9="Oui",LEN('A créer'!D9)=0),"","*SAVE") | BC9: =IF(OR('A créer'!D9="Oui",LEN('A créer'!D9)=0),"","*ML(610,125)")
A10: =IF(OR('A créer'!D10="Oui",LEN('A créer'!D10)=0),"","*FN") | B10: =IF(OR('A créer'!D10="Oui",LEN('A créer'!D10)=0),"",'A créer'!A10) | C10: =IF(OR('A créer'!D10="Oui",LEN('A créer'!D10)=0),"","Tab") | D10: =IF(OR('A créer'!D10="Oui",LEN('A créer'!D10)=0),"",'A créer'!C10) | E10: Tab 4 | F10: =IF(OR('A créer'!D10="Oui",LEN('A créer'!D10)=0),"","Tab") | G10: =IF(OR('A créer'!D10="Oui",LEN('A créer'!D10)=0),"","Tab") | H10: =IF(OR('A créer'!D10="Oui",LEN('A créer'!D10)=0),"","ENT") | I10: =IF(OR('A créer'!D10="Oui",LEN('A créer'!D10)=0),"","Oui") | J10: =IF(OR('A créer'!D10="Oui",LEN('A créer'!D10)=0),"","Tab") | K10: =IF(OR('A créer'!D10="Oui",LEN('A créer'!D10)=0),"",'A créer'!H10) | L10: =IF(OR('A créer'!D10="Oui",LEN('A créer'!D10)=0),"",IF($K10="DCW",'A créer'!G10,"")) | M10: =IF(OR('A créer'!D10="Oui",LEN('A créer'!D10)=0),"","Tab") | N10: =IF(OR('A créer'!D10="Oui",LEN('A créer'!D10)=0),"",IF($K10="DLS",'A créer'!G10,"")) | O10: =IF(OR('A créer'!D10="Oui",LEN('A créer'!D10)=0),"","Tab") | P10: =IF(OR('A créer'!D10="Oui",LEN('A créer'!D10)=0),"",IF($K10="DMS",'A créer'!G10,"")) | Q10: =IF(OR('A créer'!D10="Oui",LEN('A créer'!D10)=0),"","Tab") | R10: =IF(OR('A créer'!D10="Oui",LEN('A créer'!D10)=0),"",IF($K10="DRW",'A créer'!G10,"")) | S10: =IF(OR('A créer'!D10="Oui",LEN('A créer'!D10)=0),"","Tab") | T10: =IF(OR('A créer'!D10="Oui",LEN('A créer'!D10)=0),"",IF($K10="DSW",'A créer'!G10,"")) | U10: =IF(OR('A créer'!D10="Oui",LEN('A créer'!D10)=0),"","Tab") | V10: =IF(OR('A créer'!D10="Oui",LEN('A créer'!D10)=0),"",IF($K10="DEW",'A créer'!G10,"")) | W10: =IF(OR('A créer'!D10="Oui",LEN('A créer'!D10)=0),"","Tab") | X10: =IF(OR('A créer'!D10="Oui",LEN('A créer'!D10)=0),"",IF($K10="DNA",'A créer'!G10,"")) | Y10: =IF(OR('A créer'!D10="Oui",LEN('A créer'!D10)=0),"","Tab") | Z10: =IF(OR('A créer'!D10="Oui",LEN('A créer'!D10)=0),"",IF($K10="DOS",'A créer'!G10,"")) | AA10: =IF(OR('A créer'!D10="Oui",LEN('A créer'!D10)=0),"","Tab") | AB10: =IF(OR('A créer'!D10="Oui",LEN('A créer'!D10)=0),"","Tab") | AC10: =IF(OR('A créer'!D10="Oui",LEN('A créer'!D10)=0),"","OUI") | AD10: =IF(OR('A créer'!D10="Oui",LEN('A créer'!D10)=0),"","Tab") | AE10: =IF(OR('A créer'!D10="Oui",LEN('A créer'!D10)=0),"","ENT") | AF10: =IF(OR('A créer'!D10="Oui",LEN('A créer'!D10)=0),"","*SAVE") | AG10: =IF(OR('A créer'!D10="Oui",LEN('A créer'!D10)=0),"","*FN") | AH10: =IF(OR('A créer'!D10="Oui",LEN('A créer'!D10)=0),"",CONCATENATE("A",RIGHT('A créer'!A10,3))) | AI10: =IF(OR('A créer'!D10="Oui",LEN('A créer'!D10)=0),"","Tab") | AJ10: =IF(OR('A créer'!D10="Oui",LEN('A créer'!D10)=0),"",CONCATENATE('A créer'!A10," Regroupement")) | AK10: =IF(OR('A créer'!D10="Oui",LEN('A créer'!D10)=0),"","Tab 4") | AL10: =IF(OR('A créer'!D10="Oui",LEN('A créer'!D10)=0),"","*SB") | AM10: =IF(OR('A créer'!D10="Oui",LEN('A créer'!D10)=0),"","Tab") | AN10: =IF(OR('A créer'!D10="Oui",LEN('A créer'!D10)=0),"",CONCATENATE("A",'A créer'!A10)) | AO10: =IF(OR('A créer'!D10="Oui",LEN('A créer'!D10)=0),"","Tab") | AP10: =IF(OR('A créer'!D10="Oui",LEN('A créer'!D10)=0),"","Tab") | AQ10: =IF(OR('A créer'!D10="Oui",LEN('A créer'!D10)=0),"","ENT") | AR10: =IF(OR('A créer'!D10="Oui",LEN('A créer'!D10)=0),"","Non") | AS10: =IF(OR('A créer'!D10="Oui",LEN('A créer'!D10)=0),"","Tab") | AT10: =IF(OR('A créer'!D10="Oui",LEN('A créer'!D10)=0),"","T") | AU10: =IF(OR('A créer'!D10="Oui",LEN('A créer'!D10)=0),"","Tab") | AV10: =IF(OR('A créer'!D10="Oui",LEN('A créer'!D10)=0),"","ENT") | AW10: =IF(OR('A créer'!D10="Oui",LEN('A créer'!D10)=0),"","*SAVE") | AX10: =IF(OR('A créer'!D10="Oui",LEN('A créer'!D10)=0),"","*UP") | AY10: =IF(OR('A créer'!D10="Oui",LEN('A créer'!D10)=0),"","*Aé") | AZ10: =IF(OR('A créer'!D10="Oui",LEN('A créer'!D10)=0),"",'A créer'!A10) | BA10: =IF(OR('A créer'!D10="Oui",LEN('A créer'!D10)=0),"","Tab") | BB10: =IF(OR('A créer'!D10="Oui",LEN('A créer'!D10)=0),"","*SAVE") | BC10: =IF(OR('A créer'!D10="Oui",LEN('A créer'!D10)=0),"","*ML(610,125)")
A11: =IF(OR('A créer'!D11="Oui",LEN('A créer'!D11)=0),"","*FN") | B11: =IF(OR('A créer'!D11="Oui",LEN('A créer'!D11)=0),"",'A créer'!A11) | C11: =IF(OR('A créer'!D11="Oui",LEN('A créer'!D11)=0),"","Tab") | D11: =IF(OR('A créer'!D11="Oui",LEN('A créer'!D11)=0),"",'A créer'!C11) | E11: Tab 4 | F11: =IF(OR('A créer'!D11="Oui",LEN('A créer'!D11)=0),"","Tab") | G11: =IF(OR('A créer'!D11="Oui",LEN('A créer'!D11)=0),"","Tab") | H11: =IF(OR('A créer'!D11="Oui",LEN('A créer'!D11)=0),"","ENT") | I11: =IF(OR('A créer'!D11="Oui",LEN('A créer'!D11)=0),"","Oui") | J11: =IF(OR('A créer'!D11="Oui",LEN('A créer'!D11)=0),"","Tab") | K11: =IF(OR('A créer'!D11="Oui",LEN('A créer'!D11)=0),"",'A créer'!H11) | L11: =IF(OR('A créer'!D11="Oui",LEN('A créer'!D11)=0),"",IF($K11="DCW",'A créer'!G11,"")) | M11: =IF(OR('A créer'!D11="Oui",LEN('A créer'!D11)=0),"","Tab") | N11: =IF(OR('A créer'!D11="Oui",LEN('A créer'!D11)=0),"",IF($K11="DLS",'A créer'!G11,"")) | O11: =IF(OR('A créer'!D11="Oui",LEN('A créer'!D11)=0),"","Tab") | P11: =IF(OR('A créer'!D11="Oui",LEN('A créer'!D11)=0),"",IF($K11="DMS",'A créer'!G11,"")) | Q11: =IF(OR('A créer'!D11="Oui",LEN('A créer'!D11)=0),"","Tab") | R11: =IF(OR('A créer'!D11="Oui",LEN('A créer'!D11)=0),"",IF($K11="DRW",'A créer'!G11,"")) | S11: =IF(OR('A créer'!D11="Oui",LEN('A créer'!D11)=0),"","Tab") | T11: =IF(OR('A créer'!D11="Oui",LEN('A créer'!D11)=0),"",IF($K11="DSW",'A créer'!G11,"")) | U11: =IF(OR('A créer'!D11="Oui",LEN('A créer'!D11)=0),"","Tab") | V11: =IF(OR('A créer'!D11="Oui",LEN('A créer'!D11)=0),"",IF($K11="DEW",'A créer'!G11,"")) | W11: =IF(OR('A créer'!D11="Oui",LEN('A créer'!D11)=0),"","Tab") | X11: =IF(OR('A créer'!D11="Oui",LEN('A créer'!D11)=0),"",IF($K11="DNA",'A créer'!G11,"")) | Y11: =IF(OR('A créer'!D11="Oui",LEN('A créer'!D11)=0),"","Tab") | Z11: =IF(OR('A créer'!D11="Oui",LEN('A créer'!D11)=0),"",IF($K11="DOS",'A créer'!G11,"")) | AA11: =IF(OR('A créer'!D11="Oui",LEN('A créer'!D11)=0),"","Tab") | AB11: =IF(OR('A créer'!D11="Oui",LEN('A créer'!D11)=0),"","Tab") | AC11: =IF(OR('A créer'!D11="Oui",LEN('A créer'!D11)=0),"","OUI") | AD11: =IF(OR('A créer'!D11="Oui",LEN('A créer'!D11)=0),"","Tab") | AE11: =IF(OR('A créer'!D11="Oui",LEN('A créer'!D11)=0),"","ENT") | AF11: =IF(OR('A créer'!D11="Oui",LEN('A créer'!D11)=0),"","*SAVE") | AG11: =IF(OR('A créer'!D11="Oui",LEN('A créer'!D11)=0),"","*FN") | AH11: =IF(OR('A créer'!D11="Oui",LEN('A créer'!D11)=0),"",CONCATENATE("A",RIGHT('A créer'!A11,3))) | AI11: =IF(OR('A créer'!D11="Oui",LEN('A créer'!D11)=0),"","Tab") | AJ11: =IF(OR('A créer'!D11="Oui",LEN('A créer'!D11)=0),"",CONCATENATE('A créer'!A11," Regroupement")) | AK11: =IF(OR('A créer'!D11="Oui",LEN('A créer'!D11)=0),"","Tab 4") | AL11: =IF(OR('A créer'!D11="Oui",LEN('A créer'!D11)=0),"","*SB") | AM11: =IF(OR('A créer'!D11="Oui",LEN('A créer'!D11)=0),"","Tab") | AN11: =IF(OR('A créer'!D11="Oui",LEN('A créer'!D11)=0),"",CONCATENATE("A",'A créer'!A11)) | AO11: =IF(OR('A créer'!D11="Oui",LEN('A créer'!D11)=0),"","Tab") | AP11: =IF(OR('A créer'!D11="Oui",LEN('A créer'!D11)=0),"","Tab") | AQ11: =IF(OR('A créer'!D11="Oui",LEN('A créer'!D11)=0),"","ENT") | AR11: =IF(OR('A créer'!D11="Oui",LEN('A créer'!D11)=0),"","Non") | AS11: =IF(OR('A créer'!D11="Oui",LEN('A créer'!D11)=0),"","Tab") | AT11: =IF(OR('A créer'!D11="Oui",LEN('A créer'!D11)=0),"","T") | AU11: =IF(OR('A créer'!D11="Oui",LEN('A créer'!D11)=0),"","Tab") | AV11: =IF(OR('A créer'!D11="Oui",LEN('A créer'!D11)=0),"","ENT") | AW11: =IF(OR('A créer'!D11="Oui",LEN('A créer'!D11)=0),"","*SAVE") | AX11: =IF(OR('A créer'!D11="Oui",LEN('A créer'!D11)=0),"","*UP") | AY11: =IF(OR('A créer'!D11="Oui",LEN('A créer'!D11)=0),"","*Aé") | AZ11: =IF(OR('A créer'!D11="Oui",LEN('A créer'!D11)=0),"",'A créer'!A11) | BA11: =IF(OR('A créer'!D11="Oui",LEN('A créer'!D11)=0),"","Tab") | BB11: =IF(OR('A créer'!D11="Oui",LEN('A créer'!D11)=0),"","*SAVE") | BC11: =IF(OR('A créer'!D11="Oui",LEN('A créer'!D11)=0),"","*ML(610,125)")
A12: =IF(OR('A créer'!D12="Oui",LEN('A créer'!D12)=0),"","*FN") | B12: =IF(OR('A créer'!D12="Oui",LEN('A créer'!D12)=0),"",'A créer'!A12) | C12: =IF(OR('A créer'!D12="Oui",LEN('A créer'!D12)=0),"","Tab") | D12: =IF(OR('A créer'!D12="Oui",LEN('A créer'!D12)=0),"",'A créer'!C12) | E12: Tab 4 | F12: =IF(OR('A créer'!D12="Oui",LEN('A créer'!D12)=0),"","Tab") | G12: =IF(OR('A créer'!D12="Oui",LEN('A créer'!D12)=0),"","Tab") | H12: =IF(OR('A créer'!D12="Oui",LEN('A créer'!D12)=0),"","ENT") | I12: =IF(OR('A créer'!D12="Oui",LEN('A créer'!D12)=0),"","Oui") | J12: =IF(OR('A créer'!D12="Oui",LEN('A créer'!D12)=0),"","Tab") | K12: =IF(OR('A créer'!D12="Oui",LEN('A créer'!D12)=0),"",'A créer'!H12) | L12: =IF(OR('A créer'!D12="Oui",LEN('A créer'!D12)=0),"",IF($K12="DCW",'A créer'!G12,"")) | M12: =IF(OR('A créer'!D12="Oui",LEN('A créer'!D12)=0),"","Tab") | N12: =IF(OR('A créer'!D12="Oui",LEN('A créer'!D12)=0),"",IF($K12="DLS",'A créer'!G12,"")) | O12: =IF(OR('A créer'!D12="Oui",LEN('A créer'!D12)=0),"","Tab") | P12: =IF(OR('A créer'!D12="Oui",LEN('A créer'!D12)=0),"",IF($K12="DMS",'A créer'!G12,"")) | Q12: =IF(OR('A créer'!D12="Oui",LEN('A créer'!D12)=0),"","Tab") | R12: =IF(OR('A créer'!D12="Oui",LEN('A créer'!D12)=0),"",IF($K12="DRW",'A créer'!G12,"")) | S12: =IF(OR('A créer'!D12="Oui",LEN('A créer'!D12)=0),"","Tab") | T12: =IF(OR('A créer'!D12="Oui",LEN('A créer'!D12)=0),"",IF($K12="DSW",'A créer'!G12,"")) | U12: =IF(OR('A créer'!D12="Oui",LEN('A créer'!D12)=0),"","Tab") | V12: =IF(OR('A créer'!D12="Oui",LEN('A créer'!D12)=0),"",IF($K12="DEW",'A créer'!G12,"")) | W12: =IF(OR('A créer'!D12="Oui",LEN('A créer'!D12)=0),"","Tab") | X12: =IF(OR('A créer'!D12="Oui",LEN('A créer'!D12)=0),"",IF($K12="DNA",'A créer'!G12,"")) | Y12: =IF(OR('A créer'!D12="Oui",LEN('A créer'!D12)=0),"","Tab") | Z12: =IF(OR('A créer'!D12="Oui",LEN('A créer'!D12)=0),"",IF($K12="DOS",'A créer'!G12,"")) | AA12: =IF(OR('A créer'!D12="Oui",LEN('A créer'!D12)=0),"","Tab") | AB12: =IF(OR('A créer'!D12="Oui",LEN('A créer'!D12)=0),"","Tab") | AC12: =IF(OR('A créer'!D12="Oui",LEN('A créer'!D12)=0),"","OUI") | AD12: =IF(OR('A créer'!D12="Oui",LEN('A créer'!D12)=0),"","Tab") | AE12: =IF(OR('A créer'!D12="Oui",LEN('A créer'!D12)=0),"","ENT") | AF12: =IF(OR('A créer'!D12="Oui",LEN('A créer'!D12)=0),"","*SAVE") | AG12: =IF(OR('A créer'!D12="Oui",LEN('A créer'!D12)=0),"","*FN") | AH12: =IF(OR('A créer'!D12="Oui",LEN('A créer'!D12)=0),"",CONCATENATE("A",RIGHT('A créer'!A12,3))) | AI12: =IF(OR('A créer'!D12="Oui",LEN('A créer'!D12)=0),"","Tab") | AJ12: =IF(OR('A créer'!D12="Oui",LEN('A créer'!D12)=0),"",CONCATENATE('A créer'!A12," Regroupement")) | AK12: =IF(OR('A créer'!D12="Oui",LEN('A créer'!D12)=0),"","Tab 4") | AL12: =IF(OR('A créer'!D12="Oui",LEN('A créer'!D12)=0),"","*SB") | AM12: =IF(OR('A créer'!D12="Oui",LEN('A créer'!D12)=0),"","Tab") | AN12: =IF(OR('A créer'!D12="Oui",LEN('A créer'!D12)=0),"",CONCATENATE("A",'A créer'!A12)) | AO12: =IF(OR('A créer'!D12="Oui",LEN('A créer'!D12)=0),"","Tab") | AP12: =IF(OR('A créer'!D12="Oui",LEN('A créer'!D12)=0),"","Tab") | AQ12: =IF(OR('A créer'!D12="Oui",LEN('A créer'!D12)=0),"","ENT") | AR12: =IF(OR('A créer'!D12="Oui",LEN('A créer'!D12)=0),"","Non") | AS12: =IF(OR('A créer'!D12="Oui",LEN('A créer'!D12)=0),"","Tab") | AT12: =IF(OR('A créer'!D12="Oui",LEN('A créer'!D12)=0),"","T") | AU12: =IF(OR('A créer'!D12="Oui",LEN('A créer'!D12)=0),"","Tab") | AV12: =IF(OR('A créer'!D12="Oui",LEN('A créer'!D12)=0),"","ENT") | AW12: =IF(OR('A créer'!D12="Oui",LEN('A créer'!D12)=0),"","*SAVE") | AX12: =IF(OR('A créer'!D12="Oui",LEN('A créer'!D12)=0),"","*UP") | AY12: =IF(OR('A créer'!D12="Oui",LEN('A créer'!D12)=0),"","*Aé") | AZ12: =IF(OR('A créer'!D12="Oui",LEN('A créer'!D12)=0),"",'A créer'!A12) | BA12: =IF(OR('A créer'!D12="Oui",LEN('A créer'!D12)=0),"","Tab") | BB12: =IF(OR('A créer'!D12="Oui",LEN('A créer'!D12)=0),"","*SAVE") | BC12: =IF(OR('A créer'!D12="Oui",LEN('A créer'!D12)=0),"","*ML(610,125)")
