Workbook
Name ECO_Périmètres: OFFSET('Liste_responsabilites types'!#REF!,,,COUNTA('Liste_responsabilites types'!#REF!)-1)
Name ECO_Profils: OFFSET('Liste_responsabilites types'!#REF!,,,COUNTA('Liste_responsabilites types'!#REF!)-1)
Name OA_Responsabilites: 'Liste_responsabilites types'!$B$1:$B$36
Name OAP_Responsabilités: OFFSET('Liste_responsabilites types'!#REF!,,,COUNTA('Liste_responsabilites types'!$B:$B)-1)

Sheet Formulaire
A1: Formulaire de gestion des accès Oracle Dalkia
D2: UTILISATEUR
D3: Nom
D4: Prénom
D5: DKCode
D6: Matricule
A8: RESPONSABILITES A AJOUTER / MODIFIER / SUPPRIMER
A9: Modèle responsabilité | B9: Société (YYYY) | C9: Nom société | D9: Code région (XXX) | E9: Nom région | F9: Responsabilité | G9: Date de fin (si suppression accès)
A10: Exemples : voir l'onglet "Liste_Responsabilités types", partie grisée
C11: =IF(B11>0,VLOOKUP(B11,Liste_stes_actives!$A:$B,2,FALSE),"") | E11: =IF(D11>0,VLOOKUP(D11,Liste_regions!$A$2:$B$9,2,FALSE),"") | F11: =SUBSTITUTE(SUBSTITUTE(A11,"YYYY",B11),"XXX",D11)
C12: =IF(B12>0,VLOOKUP(B12,Liste_stes_actives!$A:$B,2,FALSE),"") | E12: =IF(D12>0,VLOOKUP(D12,Liste_regions!$A$2:$B$9,2,FALSE),"") | F12: =SUBSTITUTE(SUBSTITUTE(A12,"YYYY",B12),"XXX",D12)
C13: =IF(B13>0,VLOOKUP(B13,Liste_stes_actives!$A:$B,2,FALSE),"") | E13: =IF(D13>0,VLOOKUP(D13,Liste_regions!$A$2:$B$9,2,FALSE),"") | F13: =SUBSTITUTE(SUBSTITUTE(A13,"YYYY",B13),"XXX",D13)
C14: =IF(B14>0,VLOOKUP(B14,Liste_stes_actives!$A:$B,2,FALSE),"") | E14: =IF(D14>0,VLOOKUP(D14,Liste_regions!$A$2:$B$9,2,FALSE),"") | F14: =SUBSTITUTE(SUBSTITUTE(A14,"YYYY",B14),"XXX",D14)
C15: =IF(B15>0,VLOOKUP(B15,Liste_stes_actives!$A:$B,2,FALSE),"") | E15: =IF(D15>0,VLOOKUP(D15,Liste_regions!$A$2:$B$9,2,FALSE),"") | F15: =SUBSTITUTE(SUBSTITUTE(A15,"YYYY",B15),"XXX",D15)
C16: =IF(B16>0,VLOOKUP(B16,Liste_stes_actives!$A:$B,2,FALSE),"") | E16: =IF(D16>0,VLOOKUP(D16,Liste_regions!$A$2:$B$9,2,FALSE),"") | F16: =SUBSTITUTE(SUBSTITUTE(A16,"YYYY",B16),"XXX",D16)
C17: =IF(B17>0,VLOOKUP(B17,Liste_stes_actives!$A:$B,2,FALSE),"") | E17: =IF(D17>0,VLOOKUP(D17,Liste_regions!$A$2:$B$9,2,FALSE),"") | F17: =SUBSTITUTE(SUBSTITUTE(A17,"YYYY",B17),"XXX",D17)
C18: =IF(B18>0,VLOOKUP(B18,Liste_stes_actives!$A:$B,2,FALSE),"") | E18: =IF(D18>0,VLOOKUP(D18,Liste_regions!$A$2:$B$9,2,FALSE),"") | F18: =SUBSTITUTE(SUBSTITUTE(A18,"YYYY",B18),"XXX",D18)
C19: =IF(B19>0,VLOOKUP(B19,Liste_stes_actives!$A:$B,2,FALSE),"") | E19: =IF(D19>0,VLOOKUP(D19,Liste_regions!$A$2:$B$9,2,FALSE),"") | F19: =SUBSTITUTE(SUBSTITUTE(A19,"YYYY",B19),"XXX",D19)
C20: =IF(B20>0,VLOOKUP(B20,Liste_stes_actives!$A:$B,2,FALSE),"") | E20: =IF(D20>0,VLOOKUP(D20,Liste_regions!$A$2:$B$9,2,FALSE),"") | F20: =SUBSTITUTE(SUBSTITUTE(A20,"YYYY",B20),"XXX",D20)
C21: =IF(B21>0,VLOOKUP(B21,Liste_stes_actives!$A:$B,2,FALSE),"") | E21: =IF(D21>0,VLOOKUP(D21,Liste_regions!$A$2:$B$9,2,FALSE),"") | F21: =SUBSTITUTE(SUBSTITUTE(A21,"YYYY",B21),"XXX",D21)
C22: =IF(B22>0,VLOOKUP(B22,Liste_stes_actives!$A:$B,2,FALSE),"") | E22: =IF(D22>0,VLOOKUP(D22,Liste_regions!$A$2:$B$9,2,FALSE),"") | F22: =SUBSTITUTE(SUBSTITUTE(A22,"YYYY",B22),"XXX",D22)
... C70: =IF(B70>0,VLOOKUP(B70,Liste_stes_actives!$A:$B,2,FALSE),"") | E70: =IF(D70>0,VLOOKUP(D70,Liste_regions!$A$2:$B$9,2,FALSE),"") | F70: =SUBSTITUTE(SUBSTITUTE(A70,"YYYY",B70),"XXX",D70)

Sheet Liste_responsabilites types
A1: Module / Thème | B1: OA_Responsabilites Types | C1: qqs exemples (non exhaustifs)
A2: AP - Module Fournisseurs | B2: XXX_AP_CONSULTATION | C2: DEW_AP_CONSULTATION
B3: YYYY_AP_CONSULTATION | C3: 0119_AP_CONSULTATION
B4: XXXYYYY_AP_CONSULTATION | C4: DOS0001_AP_CONSULTATION
B5: XXXYYYY_AP_DEBLOCAGE NDF | C5: DRW0001_AP_DEBLOCAGE NDF
B6: XXXYYYY_AP_SAISIE FACT RGLT | C6: DLS0001_AP_SAISIE FACT RGLT
A7: AR - Module Clients | B7: XXX_AR_CONSULTATION | C7: DEW_AR_CONSULTATION
B8: YYYY_AR_CONSULTATION | C8: 0557_AR_CONSULTATION
B9: YYYY_AR_CONSULTATION RECOUVREMENT | C9: 0001_AR_CONSULTATION RECOUVREMENT
B10: XXXYYYY_AR_SAISIE | C10: DCW0001_AR_SAISIE
B11: XXX_AR_ANNUL_REGLEMENT | C11: DNA_AR_ANNUL_REGLEMENT
B12: XXX_AR_REMB_AVOIRS | C12: DEW_AR_REMB_AVOIRS
B13: XXXYYYY_AR_ANNUL_REGLEMENT | C13: DEW0001_AR_ANNUL_REGLEMENT
B14: YYYY_ENCAISSEMENT_AR_MULTI_REGION | C14: 0001_ENCAISSEMENT_AR_MULTI_REGION
A15: DKA | B15: DKA : Recherche UO | C15: DKA : Recherche UO
B16: DKA_AP_CONSULTATION | C16: DKA_AP_CONSULTATION
B17: DKA_AP_CONSULTATION_REFERENTIEL | C17: DKA_AP_CONSULTATION_REFERENTIEL
B18: DKA_AR_CONSULTATION | C18: DKA_AR_CONSULTATION
B19: DKA_AR_SAISIE | C19: DKA_AR_SAISIE
B20: DKA_CONTRAT_SOUS-TRAITANCE_CONSULTATION | C20: DKA_CONTRAT_SOUS-TRAITANCE_CONSULTATION
B21: DKA_GESTION_NOTIFICATIONS | C21: DKA_GESTION_NOTIFICATIONS
B22: DKA_GL_CONSULTATION | C22: DKA_GL_CONSULTATION
B23: DKA_GL_LEGALE_ADMINISTRATEUR | C23: DKA_GL_LEGALE_ADMINISTRATEUR
B24: DKA_GL_LEGALE_CONSULTATION | C24: DKA_GL_LEGALE_CONSULTATION
B25: DKA_GL_SAISIE | C25: DKA_GL_SAISIE
B26: DKA_PA_CONSULTATION | C26: DKA_PA_CONSULTATION
B27: DKA_PO_SUPERUTILISATEUR | C27: DKA_PO_SUPERUTILISATEUR
A28: RB (Rapprochement Bancaire) | B28: DKA_RB_RAPPROCHEMENT_BANCAIRE | C28: DKA_RB_RAPPROCHEMENT_BANCAIRE
B29: DKA_RB_RESPONSABLE_RAPPROCHEMENT | C29: DKA_RB_RESPONSABLE_RAPPROCHEMENT
B30: DKA_REFERENTIEL_BANCAIRE | C30: DKA_REFERENTIEL_BANCAIRE
A31: GL - Module comptable | B31: XXX_GL_CONSULTATION | C31: DSW_GL_CONSULTATION
B32: YYYY_GL_CONSULTATION | C32: 0001_GL_CONSULTATION
B33: XXX_GL_LEGALE_CONSULTATION | C33: DMS_GL_LEGALE_CONSULTATION
B34: XXX_GL_SAISIE | C34: DEW_GL_SAISIE
B35: YYYY_GL_SAISIE | C35: 0470_GL_SAISIE
B36: YYYY_GL_LEGALE_CONSULTATION | C36: 0001_GL_LEGALE_CONSULTATION
A37: FA (immobilisations) | B37: YYYY_FA_CONSULTATION | C37: 0001_FA_CONSULTATION
B38: YYYY_FA_SAISIE | C38: 0001_FA_SAISIE
A39: PA (Projets) | B39: XXX_PA_CONSULTATION | C39: DEW_PA_CONSULTATION
B40: YYYY_PA_CONSULTATION | C40: 0001_PA_CONSULTATION
...

Sheet Liste_regions
A1: Trigramme Région | B1: Nom complet de la Région
A2: DCW | B2: Est
A3: DEW | B3: Méditerrannée
A4: DLS | B4: Centre-Ouest
A5: DMS | B5: Centre-Est
A6: DNA | B6: Sud-Ouest
A7: DOS | B7: Siège
A8: DRW | B8: Ile-de-France
A9: DSW | B9: Nord-Ouest

Sheet Liste_stes_actives
A1: SHORT_NAME | B1: NAME | E1: (au 22/05/2025)
A2: 0001 | B2: DALKIA
A3: 0013 | B3: BEH
A4: 0028 | B4: ENERLAY
A5: 0034 | B5: SCBC
A6: 0047 | B6: COCHAREC
A7: 0049 | B7: BERJALIA
A8: 0051 | B8: S.T.H.A.L.
A9: 0067 | B9: SOFLEC
A10: 0069 | B10: SOMUSSY
A11: 0070 | B11: BOISMARINE
A12: 0074 | B12: SONITHERM
A13: 0076 | B13: NBI
... A304: 0930 | B304: S.O.G.E.T.

Sheet Site_CSP
A1: Nom du site CSP | B1: Code site CSP
A2: LILLE | B2: LIL
A3: LYON | B3: LYO
A4: NANTES | B4: NAN
A5: IDF | B5: IDF

Sheet Révisions
A1: Date | B1: qui | C1: quoi
A2: 45623 | B2: pgrall | C2: Liste des sociétés actives + tri par ordre des responsabilités.
A3: 45799 | B3: pgrall | C3: Revu des responaabilités actives dans Oracle + regrouepement Finance/achat dans la meme fiche suite passage SSTR chez Dacshop
